Workbook

Sheet Main Table
A1: 1 | B1: 2 | C1: 3 | D1: 4 | E1: 5 | F1: 6 | G1: 7 | H1: 8 | I1: 9 | J1: 10 | K1: 11 | L1: 12 | M1: 13 | N1: 14 | O1: 15 | P1: 16 | Q1: 17 | R1: 18
A2: H | R2: He
A3: Li | B3: Be | M3: B | N3: C | O3: N | P3: O | Q3: P | R3: Ne
A4: Na | B4: Mg | M4: Al | N4: Si | O4: P | P4: P | Q4: Cl | R4: Ar
A5: K | B5: Ca | C5: Sc | D5: Ti | E5: V | F5: Cr | G5: Mn | H5: Fe | I5: Co | J5: Ni | K5: Cu | L5: Zn | M5: Ga | N5: Ge | O5: As | P5: As | Q5: Br | R5: Kr
A6: Rb | B6: Sr | C6: Y | D6: Zr | E6: Nb | F6: Mo | G6: Tc | H6: Ru | I6: Rh | J6: Pd | K6: Ag | L6: Cd | M6: In | N6: Sn | O6: Sb | P6: Sb | Q6: I | R6: Xe
A7: Cs | B7: Ba | D7: Hf | E7: Ta | F7: W | G7: Re | H7: Os | I7: Ir | J7: Pt | K7: Au | L7: Hg | M7: Ti | N7: Pb | O7: Bi | P7: Bi | Q7: At | R7: Rn
A8: Fr | B8: Ra | D8: Rf | E8: Db | F8: Sg | G8: Bh | H8: Hs | I8: Mt | J8: Ds | K8: Rg | L8: Cn | M8: Nh | N8: Fl | O8: Mc | P8: Lv | Q8: Ts | R8: Og
C9: La | D9: Ce | E9: Pr | F9: Nd | G9: Pm | H9: Sm | I9: Eu | J9: Gd | K9: Tb | L9: Dy | M9: Ho | N9: Er | O9: Tm | P9: Yb | Q9: Lu
C10: Ac | D10: Th | E10: Pa | F10: U | G10: Np | H10: Pu | I10: Am | J10: Cm | K10: Bk | L10: Cf | M10: Es | N10: Fm | O10: Md | P10: No | Q10: Lr

Sheet Elements
A1: 1 | B1: Hydrogen | C1: H | D1: Nonmetal | E1: 1 | F1: 0 | G1: =(A1 * 1.007276) + (F1 * 1.008665) + (L1 * 0.00054858) -> 1.0078246 | H1: =(G1-(A1*'Atomic Particles'!C1))/'Atomic Particles'!C2+A1 -> 1.0005427 | I1: =0.529177210544 * (M1^2 / (A1 - AG1)) -> 0.52917721 | J1: =(('Atomic Particles'!C1)*A1)+(('Atomic Particles'!C2)*Elements!F1) -> 1.0072772 | K1: =(E1^(1/3))*Constants!B2 -> 1.25e-15 | L1: 1 | M1: 1 | AF1: 1 | AG1: =IF(A1=1, 0, IF(A1=2, 0.3, IF(A1<=10, 0.35*(N1+O1-1)+0.85*M1, IF(A1<=18, 0.35*(P1+Q1-1)+0.85*(N1+O1)+M1, IF(A1<=36, 0.35*(S1+T1-1)+0.85*(P1+Q1+R1)+(M1+N1+O1), IF(A1<=54, 0.35*(W1+X1-1)+0.85*(S1+T1+U1)+(M1+N1+O1+P1+Q1+R1), IF(A1<=86, 0.35*(AA1+AB1-1)+0.85*(W1+X1+Y1+Z1)+(M1+N1+O1+P1+Q1+R1+S1+T1+U1+V1), IF(A1<=118, 0.35*(AD1+AE1-1)+0.85*(AA1+AB1+AC1)+(M1+N1+O1+P1+Q1+R1+S1+T1+U1+V1+W1+X1+Y1+Z1), 0)))))))) -> 0 | AH1: =(G1 * 1.6605E-24) / (AI1 * 1E-24) -> 2.6960741 | AI1: =(4/3) * PI() * (I1^3) -> 0.62071467 | AJ1: =(A1*1.67262192369E-27 + F1*1.67492749804E-27 + L1*9.1093837015E-31) / 1.6605390666E-27 -> 1.007825 | AM1: =(A1) - (L1) -> 0 | AN1: =A1-AG1 -> 1 | AO1: =4 * PI() * 8.854187817E-12 * (I1 * 0.0000000001)^3 -> 1.6487773e-41 | AP1: =AO1 * 10^12 -> 1.6487773e-29 | AQ1: =(1 / (2 * 3.14159265358979)) * SQRT((A1 * (1.602176634E-19^2)) / ((AI1 * 1E-30) * 9.1093837015E-31 * 8.8541878128E-12)) -> 1.1396347e+16 | AR1: =I1 * 350 -> 185.21202 | AS1: =299792458000000000 / AQ1 -> 26.306014
A2: 2 | B2: Helium | C2: He | D2: Noble Gas | E2: 4 | F2: =E2-A2 -> 2 | G2: =(A2 * 1.007276) + (F2 * 1.008665) + (L2 * 0.00054858) -> 4.0329792 | H2: =(G2-(A2*'Atomic Particles'!C1))/'Atomic Particles'!C2+A2 -> 4.0010835 | I2: =0.529177210544 * (M2^2 / (A2 - AG2)) -> 1.2451228 | J2: =(('Atomic Particles'!C1)*A2)+(('Atomic Particles'!C2)*Elements!F2) -> 4.0318863 | K2: =(E2^(1/3))*Constants!B2 -> 1.9842513e-15 | L2: 2 | M2: 2 | AF2: 1 | AG2: =IF(A2=1, 0, IF(A2=2, 0.3, IF(A2<=10, 0.35*(N2+O2-1)+0.85*M2, IF(A2<=18, 0.35*(P2+Q2-1)+0.85*(N2+O2)+M2, IF(A2<=36, 0.35*(S2+T2-1)+0.85*(P2+Q2+R2)+(M2+N2+O2), IF(A2<=54, 0.35*(W2+X2-1)+0.85*(S2+T2+U2)+(M2+N2+O2+P2+Q2+R2), IF(A2<=86, 0.35*(AA2+AB2-1)+0.85*(W2+X2+Y2+Z2)+(M2+N2+O2+P2+Q2+R2+S2+T2+U2+V2), IF(A2<=118, 0.35*(AD2+AE2-1)+0.85*(AA2+AB2+AC2)+(M2+N2+O2+P2+Q2+R2+S2+T2+U2+V2+W2+X2+Y2+Z2), 0)))))))) -> 0.3 | AH2: =(G2 * 1.6605E-24) / (AI2 * 1E-24) -> 0.82820842 | AI2: =(4/3) * PI() * (I2^3) -> 8.0858414 | AJ2: =(A2*1.67262192369E-27 + F2*1.67492749804E-27 + L2*9.1093837015E-31) / 1.6605390666E-27 -> 4.0329799 | AM2: =A2 - L2 -> 0 | AN2: =A2-AG2 -> 1.7 | AO2: =4 * PI() * 8.854187817E-12 * (I2 * 0.0000000001)^3 -> 2.1478067e-40 | AP2: =AO2 * 10^12 -> 2.1478067e-28 | AQ2: =(1 / (2 * 3.14159265358979)) * SQRT((A2 * (1.602176634E-19^2)) / ((AI2 * 1E-30) * 9.1093837015E-31 * 8.8541878128E-12)) -> 4.4654379e+15 | AR2: =I2 * 350 -> 435.793 | AS2: =299792458000000000 / AQ2 -> 67.136184
A3: 3 | B3: Lithium | C3: Li | D3: Alkali Metal | E3: 7 | F3: =E3-A3 -> 4 | G3: =(A3 * 1.007276) + (F3 * 1.008665) + (L3 * 0.00054858) -> 7.0581337 | H3: =(G3-(A3*'Atomic Particles'!C1))/'Atomic Particles'!C2+A3 -> 7.0016243 | I3: =0.529177210544 * (M3^2 / (A3 - AG3)) -> 1.6282376 | J3: =(('Atomic Particles'!C1)*A3)+(('Atomic Particles'!C2)*Elements!F3) -> 7.0564953 | K3: =(E3^(1/3))*Constants!B2 -> 2.391164e-15 | L3: 3 | M3: 2 | N3: 1 | AF3: 2 | AG3: =IF(A3=1, 0, IF(A3=2, 0.3, IF(A3<=10, 0.35*(N3+O3-1)+0.85*M3, IF(A3<=18, 0.35*(P3+Q3-1)+0.85*(N3+O3)+M3, IF(A3<=36, 0.35*(S3+T3-1)+0.85*(P3+Q3+R3)+(M3+N3+O3), IF(A3<=54, 0.35*(W3+X3-1)+0.85*(S3+T3+U3)+(M3+N3+O3+P3+Q3+R3), IF(A3<=86, 0.35*(AA3+AB3-1)+0.85*(W3+X3+Y3+Z3)+(M3+N3+O3+P3+Q3+R3+S3+T3+U3+V3), IF(A3<=118, 0.35*(AD3+AE3-1)+0.85*(AA3+AB3+AC3)+(M3+N3+O3+P3+Q3+R3+S3+T3+U3+V3+W3+X3+Y3+Z3), 0)))))))) -> 1.7 | AH3: =(G3 * 1.6605E-24) / (AI3 * 1E-24) -> 0.64816688 | AI3: =(4/3) * PI() * (I3^3) -> 18.081811 | AJ3: =(A3*1.67262192369E-27 + F3*1.67492749804E-27 + L3*9.1093837015E-31) / 1.6605390666E-27 -> 7.0581348 | AM3: =A3 - L3 -> 0 | AN3: =A3-AG3 -> 1.3 | AO3: =4 * PI() * 8.854187817E-12 * (I3 * 0.0000000001)^3 -> 4.8029925e-40 | AP3: =AO3 * 10^12 -> 4.8029925e-28 | AQ3: =(1 / (2 * 3.14159265358979)) * SQRT((A3 * (1.602176634E-19^2)) / ((AI3 * 1E-30) * 9.1093837015E-31 * 8.8541878128E-12)) -> 3.657222e+15 | AR3: =I3 * 350 -> 569.88315 | AS3: =299792458000000000 / AQ3 -> 81.972726
A4: 4 | B4: beryllium | C4: Be | D4: Alkali Earth Metal | E4: 9 | F4: =E4-A4 -> 5 | G4: =(A4 * 1.007276) + (F4 * 1.008665) + (L4 * 0.00054858) -> 9.0746233 | H4: =(G4-(A4*'Atomic Particles'!C1))/'Atomic Particles'!C2+A4 -> 9.0021661 | I4: =0.529177210544 * (M4^2 / (A4 - AG4)) -> 1.0854917 | J4: =(('Atomic Particles'!C1)*A4)+(('Atomic Particles'!C2)*Elements!F4) -> 9.0724384 | K4: =(E4^(1/3))*Constants!B2 -> 2.6001048e-15 | L4: 4 | M4: 2 | N4: 2 | AF4: 2 | AG4: =IF(A4=1, 0, IF(A4=2, 0.3, IF(A4<=10, 0.35*(N4+O4-1)+0.85*M4, IF(A4<=18, 0.35*(P4+Q4-1)+0.85*(N4+O4)+M4, IF(A4<=36, 0.35*(S4+T4-1)+0.85*(P4+Q4+R4)+(M4+N4+O4), IF(A4<=54, 0.35*(W4+X4-1)+0.85*(S4+T4+U4)+(M4+N4+O4+P4+Q4+R4), IF(A4<=86, 0.35*(AA4+AB4-1)+0.85*(W4+X4+Y4+Z4)+(M4+N4+O4+P4+Q4+R4+S4+T4+U4+V4), IF(A4<=118, 0.35*(AD4+AE4-1)+0.85*(AA4+AB4+AC4)+(M4+N4+O4+P4+Q4+R4+S4+T4+U4+V4+W4+X4+Y4+Z4), 0)))))))) -> 2.05 | AH4: =(G4 * 1.6605E-24) / (AI4 * 1E-24) -> 2.8125441 | AI4: =(4/3) * PI() * (I4^3) -> 5.3575736 | AJ4: =(A4*1.67262192369E-27 + F4*1.67492749804E-27 + L4*9.1093837015E-31) / 1.6605390666E-27 -> 9.0746248 | AM4: =A4 - L4 -> 0 | AN4: =A4-AG4 -> 1.95 | AO4: =4 * PI() * 8.854187817E-12 * (I4 * 0.0000000001)^3 -> 1.4231089e-40 | AP4: =AO4 * 10^12 -> 1.4231089e-28 | AQ4: =(1 / (2 * 3.14159265358979)) * SQRT((A4 * (1.602176634E-19^2)) / ((AI4 * 1E-30) * 9.1093837015E-31 * 8.8541878128E-12)) -> 7.7581395e+15 | AR4: =I4 * 350 -> 379.9221 | AS4: =299792458000000000 / AQ4 -> 38.642313
A5: 5 | B5: Boron | C5: B | D5: Metalloid | E5: 10 | F5: =E5-A5 -> 5 | G5: =(A5 * 1.007276) + (F5 * 1.008665) + (L5 * 0.00054858) -> 10.082448 | H5: =(G5-(A5*'Atomic Particles'!C1))/'Atomic Particles'!C2+A5 -> 10.002709 | I5: =0.529177210544 * (M5^2 / (A5 - AG5)) -> 0.81411879 | J5: =(('Atomic Particles'!C1)*A5)+(('Atomic Particles'!C2)*Elements!F5) -> 10.079716 | K5: =(E5^(1/3))*Constants!B2 -> 2.6930434e-15 | L5: 5 | M5: 2 | N5: 2 | O5: 1 | AF5: 2 | AG5: =IF(A5=1, 0, IF(A5=2, 0.3, IF(A5<=10, 0.35*(N5+O5-1)+0.85*M5, IF(A5<=18, 0.35*(P5+Q5-1)+0.85*(N5+O5)+M5, IF(A5<=36, 0.35*(S5+T5-1)+0.85*(P5+Q5+R5)+(M5+N5+O5), IF(A5<=54, 0.35*(W5+X5-1)+0.85*(S5+T5+U5)+(M5+N5+O5+P5+Q5+R5), IF(A5<=86, 0.35*(AA5+AB5-1)+0.85*(W5+X5+Y5+Z5)+(M5+N5+O5+P5+Q5+R5+S5+T5+U5+V5), IF(A5<=118, 0.35*(AD5+AE5-1)+0.85*(AA5+AB5+AC5)+(M5+N5+O5+P5+Q5+R5+S5+T5+U5+V5+W5+X5+Y5+Z5), 0)))))))) -> 2.4 | AH5: =(G5 * 1.6605E-24) / (AI5 * 1E-24) -> 7.4071805 | AI5: =(4/3) * PI() * (I5^3) -> 2.2602264 | AJ5: =(A5*1.67262192369E-27 + F5*1.67492749804E-27 + L5*9.1093837015E-31) / 1.6605390666E-27 -> 10.08245 | AM5: =A5 - L5 -> 0 | AN5: =A5-AG5 -> 2.6 | AO5: =4 * PI() * 8.854187817E-12 * (I5 * 0.0000000001)^3 -> 6.0037406e-41 | AP5: =AO5 * 10^12 -> 6.0037406e-29 | AQ5: =(1 / (2 * 3.14159265358979)) * SQRT((A5 * (1.602176634E-19^2)) / ((AI5 * 1E-30) * 9.1093837015E-31 * 8.8541878128E-12)) -> 1.3354287e+16 | AR5: =I5 * 350 -> 284.94157 | AS5: =299792458000000000 / AQ5 -> 22.449155
A6: 6 | B6: Carbon | C6: C | D6: Nonmetal | E6: 12 | F6: =E6-A6 -> 6 | G6: =(A6 * 1.007276) + (F6 * 1.008665) + (L6 * 0.00054858) -> 12.098937 | H6: =(G6-(A6*'Atomic Particles'!C1))/'Atomic Particles'!C2+A6 -> 12.003251 | I6: =0.529177210544 * (M6^2 / (A6 - AG6)) -> 0.65129503 | J6: =(('Atomic Particles'!C1)*A6)+(('Atomic Particles'!C2)*Elements!F6) -> 12.095659 | K6: =(E6^(1/3))*Constants!B2 -> 2.8617856e-15 | L6: 6 | M6: 2 | N6: 2 | O6: 2 | AF6: 2 | AG6: =IF(A6=1, 0, IF(A6=2, 0.3, IF(A6<=10, 0.35*(N6+O6-1)+0.85*M6, IF(A6<=18, 0.35*(P6+Q6-1)+0.85*(N6+O6)+M6, IF(A6<=36, 0.35*(S6+T6-1)+0.85*(P6+Q6+R6)+(M6+N6+O6), IF(A6<=54, 0.35*(W6+X6-1)+0.85*(S6+T6+U6)+(M6+N6+O6+P6+Q6+R6), IF(A6<=86, 0.35*(AA6+AB6-1)+0.85*(W6+X6+Y6+Z6)+(M6+N6+O6+P6+Q6+R6+S6+T6+U6+V6), IF(A6<=118, 0.35*(AD6+AE6-1)+0.85*(AA6+AB6+AC6)+(M6+N6+O6+P6+Q6+R6+S6+T6+U6+V6+W6+X6+Y6+Z6), 0)))))))) -> 2.75 | AH6: =(G6 * 1.6605E-24) / (AI6 * 1E-24) -> 17.360579 | AI6: =(4/3) * PI() * (I6^3) -> 1.1572359 | AJ6: =(A6*1.67262192369E-27 + F6*1.67492749804E-27 + L6*9.1093837015E-31) / 1.6605390666E-27 -> 12.09894 | AM6: =A6 - L6 -> 0 | AN6: =A6-AG6 -> 3.25 | AO6: =4 * PI() * 8.854187817E-12 * (I6 * 0.0000000001)^3 -> 3.0739152e-41 | AP6: =AO6 * 10^12 -> 3.0739152e-29 | AQ6: =(1 / (2 * 3.14159265358979)) * SQRT((A6 * (1.602176634E-19^2)) / ((AI6 * 1E-30) * 9.1093837015E-31 * 8.8541878128E-12)) -> 2.0444493e+16 | AR6: =I6 * 350 -> 227.95326 | AS6: =299792458000000000 / AQ6 -> 14.663727
A7: 7 | B7: Nitrogen | C7: N | D7: Nonmetal | E7: 14 | F7: =E7-A7 -> 7 | G7: =(A7 * 1.007276) + (F7 * 1.008665) + (L7 * 0.00054858) -> 14.115427 | H7: =(G7-(A7*'Atomic Particles'!C1))/'Atomic Particles'!C2+A7 -> 14.003792 | I7: =0.529177210544 * (M7^2 / (A7 - AG7)) -> 0.54274586 | J7: =(('Atomic Particles'!C1)*A7)+(('Atomic Particles'!C2)*Elements!F7) -> 14.111602 | K7: =(E7^(1/3))*Constants!B2 -> 3.0126778e-15 | L7: 7 | M7: 2 | N7: 2 | O7: 3 | AF7: 2 | AG7: =IF(A7=1, 0, IF(A7=2, 0.3, IF(A7<=10, 0.35*(N7+O7-1)+0.85*M7, IF(A7<=18, 0.35*(P7+Q7-1)+0.85*(N7+O7)+M7, IF(A7<=36, 0.35*(S7+T7-1)+0.85*(P7+Q7+R7)+(M7+N7+O7), IF(A7<=54, 0.35*(W7+X7-1)+0.85*(S7+T7+U7)+(M7+N7+O7+P7+Q7+R7), IF(A7<=86, 0.35*(AA7+AB7-1)+0.85*(W7+X7+Y7+Z7)+(M7+N7+O7+P7+Q7+R7+S7+T7+U7+V7), IF(A7<=118, 0.35*(AD7+AE7-1)+0.85*(AA7+AB7+AC7)+(M7+N7+O7+P7+Q7+R7+S7+T7+U7+V7+W7+X7+Y7+Z7), 0)))))))) -> 3.1 | AH7: =(G7 * 1.6605E-24) / (AI7 * 1E-24) -> 34.998928 | AI7: =(4/3) * PI() * (I7^3) -> 0.6696967 | AJ7: =(A7*1.67262192369E-27 + F7*1.67492749804E-27 + L7*9.1093837015E-31) / 1.6605390666E-27 -> 14.11543 | AM7: =A7 - L7 -> 0 | AN7: =A7-AG7 -> 3.9 | AO7: =4 * PI() * 8.854187817E-12 * (I7 * 0.0000000001)^3 -> 1.7788861e-41 | AP7: =AO7 * 10^12 -> 1.7788861e-29 | AQ7: =(1 / (2 * 3.14159265358979)) * SQRT((A7 * (1.602176634E-19^2)) / ((AI7 * 1E-30) * 9.1093837015E-31 * 8.8541878128E-12)) -> 2.90283e+16 | AR7: =I7 * 350 -> 189.96105 | AS7: =299792458000000000 / AQ7 -> 10.327593
A8: 8 | B8: Oxygen | C8: O | D8: Nonmetal | E8: 16 | F8: =E8-A8 -> 8 | G8: =(A8 * 1.007276) + (F8 * 1.008665) + (L8 * 0.00054858) -> 16.131917 | H8: =(G8-(A8*'Atomic Particles'!C1))/'Atomic Particles'!C2+A8 -> 16.004334 | I8: =0.529177210544 * (M8^2 / (A8 - AG8)) -> 0.46521073 | J8: =(('Atomic Particles'!C1)*A8)+(('Atomic Particles'!C2)*Elements!F8) -> 16.127545 | K8: =(E8^(1/3))*Constants!B2 -> 3.1498026e-15 | L8: 8 | M8: 2 | N8: 2 | O8: 4 | AF8: 2 | AG8: =IF(A8=1, 0, IF(A8=2, 0.3, IF(A8<=10, 0.35*(N8+O8-1)+0.85*M8, IF(A8<=18, 0.35*(P8+Q8-1)+0.85*(N8+O8)+M8, IF(A8<=36, 0.35*(S8+T8-1)+0.85*(P8+Q8+R8)+(M8+N8+O8), IF(A8<=54, 0.35*(W8+X8-1)+0.85*(S8+T8+U8)+(M8+N8+O8+P8+Q8+R8), IF(A8<=86, 0.35*(AA8+AB8-1)+0.85*(W8+X8+Y8+Z8)+(M8+N8+O8+P8+Q8+R8+S8+T8+U8+V8), IF(A8<=118, 0.35*(AD8+AE8-1)+0.85*(AA8+AB8+AC8)+(M8+N8+O8+P8+Q8+R8+S8+T8+U8+V8+W8+X8+Y8+Z8), 0)))))))) -> 3.45 | AH8: =(G8 * 1.6605E-24) / (AI8 * 1E-24) -> 63.516573 | AI8: =(4/3) * PI() * (I8^3) -> 0.4217332 | AJ8: =(A8*1.67262192369E-27 + F8*1.67492749804E-27 + L8*9.1093837015E-31) / 1.6605390666E-27 -> 16.13192 | AM8: =A8 - L8 -> 0 | AN8: =A8-AG8 -> 4.55 | AO8: =4 * PI() * 8.854187817E-12 * (I8 * 0.0000000001)^3 -> 1.1202315e-41 | AP8: =AO8 * 10^12 -> 1.1202315e-29 | AQ8: =(1 / (2 * 3.14159265358979)) * SQRT((A8 * (1.602176634E-19^2)) / ((AI8 * 1E-30) * 9.1093837015E-31 * 8.8541878128E-12)) -> 3.9105493e+16 | AR8: =I8 * 350 -> 162.82376 | AS8: =299792458000000000 / AQ8 -> 7.6662494
A9: 9 | B9: Fluorine | C9: F | D9: Halogen | E9: 19 | F9: =E9-A9 -> 10 | G9: =(A9 * 1.007276) + (F9 * 1.008665) + (L9 * 0.00054858) -> 19.157071 | H9: =(G9-(A9*'Atomic Particles'!C1))/'Atomic Particles'!C2+A9 -> 19.004875 | I9: =0.529177210544 * (M9^2 / (A9 - AG9)) -> 0.40705939 | J9: =(('Atomic Particles'!C1)*A9)+(('Atomic Particles'!C2)*Elements!F9) -> 19.152154 | K9: =(E9^(1/3))*Constants!B2 -> 3.3355021e-15 | L9: 9 | M9: 2 | N9: 2 | O9: 5 | AF9: 2 | AG9: =IF(A9=1, 0, IF(A9=2, 0.3, IF(A9<=10, 0.35*(N9+O9-1)+0.85*M9, IF(A9<=18, 0.35*(P9+Q9-1)+0.85*(N9+O9)+M9, IF(A9<=36, 0.35*(S9+T9-1)+0.85*(P9+Q9+R9)+(M9+N9+O9), IF(A9<=54, 0.35*(W9+X9-1)+0.85*(S9+T9+U9)+(M9+N9+O9+P9+Q9+R9), IF(A9<=86, 0.35*(AA9+AB9-1)+0.85*(W9+X9+Y9+Z9)+(M9+N9+O9+P9+Q9+R9+S9+T9+U9+V9), IF(A9<=118, 0.35*(AD9+AE9-1)+0.85*(AA9+AB9+AC9)+(M9+N9+O9+P9+Q9+R9+S9+T9+U9+V9+W9+X9+Y9+Z9), 0)))))))) -> 3.8 | AH9: =(G9 * 1.6605E-24) / (AI9 * 1E-24) -> 112.59161 | AI9: =(4/3) * PI() * (I9^3) -> 0.2825283 | AJ9: =(A9*1.67262192369E-27 + F9*1.67492749804E-27 + L9*9.1093837015E-31) / 1.6605390666E-27 -> 19.157075 | AM9: =A9 - L9 -> 0 | AN9: =A9-AG9 -> 5.2 | AO9: =4 * PI() * 8.854187817E-12 * (I9 * 0.0000000001)^3 -> 7.5046758e-42 | AP9: =AO9 * 10^12 -> 7.5046758e-30 | AQ9: =(1 / (2 * 3.14159265358979)) * SQRT((A9 * (1.602176634E-19^2)) / ((AI9 * 1E-30) * 9.1093837015E-31 * 8.8541878128E-12)) -> 5.0675955e+16 | AR9: =I9 * 350 -> 142.47079 | AS9: =299792458000000000 / AQ9 -> 5.9158719
A10: 10 | B10: Neon | C10: Ne | D10: Noble Gas | E10: 20 | F10: =E10-A10 -> 10 | G10: =(A10 * 1.007276) + (F10 * 1.008665) + (L10 * 0.00054858) -> 20.164896 | H10: =(G10-(A10*'Atomic Particles'!C1))/'Atomic Particles'!C2+A10 -> 20.005418 | I10: =0.529177210544 * (M10^2 / (A10 - AG10)) -> 0.36183057 | J10: =(('Atomic Particles'!C1)*A10)+(('Atomic Particles'!C2)*Elements!F10) -> 20.159431 | K10: =(E10^(1/3))*Constants!B2 -> 3.393022e-15 | L10: 10 | M10: 2 | N10: 2 | O10: 6 | AF10: 2 | AG10: =IF(A10=1, 0, IF(A10=2, 0.3, IF(A10<=10, 0.35*(N10+O10-1)+0.85*M10, IF(A10<=18, 0.35*(P10+Q10-1)+0.85*(N10+O10)+M10, IF(A10<=36, 0.35*(S10+T10-1)+0.85*(P10+Q10+R10)+(M10+N10+O10), IF(A10<=54, 0.35*(W10+X10-1)+0.85*(S10+T10+U10)+(M10+N10+O10+P10+Q10+R10), IF(A10<=86, 0.35*(AA10+AB10-1)+0.85*(W10+X10+Y10+Z10)+(M10+N10+O10+P10+Q10+R10+S10+T10+U10+V10), IF(A10<=118, 0.35*(AD10+AE10-1)+0.85*(AA10+AB10+AC10)+(M10+N10+O10+P10+Q10+R10+S10+T10+U10+V10+W10+X10+Y10+Z10), 0)))))))) -> 4.15 | AH10: =(G10 * 1.6605E-24) / (AI10 * 1E-24) -> 168.74483 | AI10: =(4/3) * PI() * (I10^3) -> 0.19842865 | AJ10: =(A10*1.67262192369E-27 + F10*1.67492749804E-27 + L10*9.1093837015E-31) / 1.6605390666E-27 -> 20.1649 | AM10: =A10 - L10 -> 0 | AN10: =A10-AG10 -> 5.85 | AO10: =4 * PI() * 8.854187817E-12 * (I10 * 0.0000000001)^3 -> 5.2707737e-42 | AP10: =AO10 * 10^12 -> 5.2707737e-30 | AQ10: =(1 / (2 * 3.14159265358979)) * SQRT((A10 * (1.602176634E-19^2)) / ((AI10 * 1E-30) * 9.1093837015E-31 * 8.8541878128E-12)) -> 6.373962e+16 | AR10: =I10 * 350 -> 126.6407 | AS10: =299792458000000000 / AQ10 -> 4.7033926
A11: 11 | B11: Sodium | C11: Na | D11: Alkali Metal | E11: 23 | F11: =E11-A11 -> 12 | G11: =(A11 * 1.007276) + (F11 * 1.008665) + (L11 * 0.00054858) -> 23.19005 | H11: =(G11-(A11*'Atomic Particles'!C1))/'Atomic Particles'!C2+A11 -> 23.005958 | I11: =0.529177210544 * (M11^2 / (A11 - AG11)) -> 0.96214038 | J11: =(('Atomic Particles'!C1)*A11)+(('Atomic Particles'!C2)*Elements!F11) -> 23.18404 | K11: =(E11^(1/3))*Constants!B2 -> 3.5548337e-15 | L11: 11 | M11: 2 | N11: 2 | O11: 6 | P11: 1 | AF11: 3 | AG11: =IF(A11=1, 0, IF(A11=2, 0.3, IF(A11<=10, 0.35*(N11+O11-1)+0.85*M11, IF(A11<=18, 0.35*(P11+Q11-1)+0.85*(N11+O11)+M11, IF(A11<=36, 0.35*(S11+T11-1)+0.85*(P11+Q11+R11)+(M11+N11+O11), IF(A11<=54, 0.35*(W11+X11-1)+0.85*(S11+T11+U11)+(M11+N11+O11+P11+Q11+R11), IF(A11<=86, 0.35*(AA11+AB11-1)+0.85*(W11+X11+Y11+Z11)+(M11+N11+O11+P11+Q11+R11+S11+T11+U11+V11), IF(A11<=118, 0.35*(AD11+AE11-1)+0.85*(AA11+AB11+AC11)+(M11+N11+O11+P11+Q11+R11+S11+T11+U11+V11+W11+X11+Y11+Z11), 0)))))))) -> 8.8 | AH11: =(G11 * 1.6605E-24) / (AI11 * 1E-24) -> 10.321353 | AI11: =(4/3) * PI() * (I11^3) -> 3.7308169 | AJ11: =(A11*1.67262192369E-27 + F11*1.67492749804E-27 + L11*9.1093837015E-31) / 1.6605390666E-27 -> 23.190055 | AM11: =A11 - L11 -> 0 | AN11: =A11-AG11 -> 2.2 | AO11: =4 * PI() * 8.854187817E-12 * (I11 * 0.0000000001)^3 -> 9.9100061e-41 | AP11: =AO11 * 10^12 -> 9.9100061e-29 | AQ11: =(1 / (2 * 3.14159265358979)) * SQRT((A11 * (1.602176634E-19^2)) / ((AI11 * 1E-30) * 9.1093837015E-31 * 8.8541878128E-12)) -> 1.5417219e+16 | AR11: =I11 * 350 -> 336.74913 | AS11: =299792458000000000 / AQ11 -> 19.445301
A12: 12 | B12: Magnesium | C12: Mg | D12: Alkali Earth Metal | E12: 24 | F12: =E12-A12 -> 12 | G12: =(A12 * 1.007276) + (F12 * 1.008665) + (L12 * 0.00054858) -> 24.197875 | H12: =(G12-(A12*'Atomic Particles'!C1))/'Atomic Particles'!C2+A12 -> 24.006501 | I12: =0.529177210544 * (M12^2 / (A12 - AG12)) -> 0.74270486 | J12: =(('Atomic Particles'!C1)*A12)+(('Atomic Particles'!C2)*Elements!F12) -> 24.191318 | K12: =(E12^(1/3))*Constants!B2 -> 3.6056239e-15 | L12: 12 | M12: 2 | N12: 2 | O12: 6 | P12: 2 | AF12: 3 | AG12: =IF(A12=1, 0, IF(A12=2, 0.3, IF(A12<=10, 0.35*(N12+O12-1)+0.85*M12, IF(A12<=18, 0.35*(P12+Q12-1)+0.85*(N12+O12)+M12, IF(A12<=36, 0.35*(S12+T12-1)+0.85*(P12+Q12+R12)+(M12+N12+O12), IF(A12<=54, 0.35*(W12+X12-1)+0.85*(S12+T12+U12)+(M12+N12+O12+P12+Q12+R12), IF(A12<=86, 0.35*(AA12+AB12-1)+0.85*(W12+X12+Y12+Z12)+(M12+N12+O12+P12+Q12+R12+S12+T12+U12+V12), IF(A12<=118, 0.35*(AD12+AE12-1)+0.85*(AA12+AB12+AC12)+(M12+N12+O12+P12+Q12+R12+S12+T12+U12+V12+W12+X12+Y12+Z12), 0)))))))) -> 9.15 | AH12: =(G12 * 1.6605E-24) / (AI12 * 1E-24) -> 23.414167 | AI12: =(4/3) * PI() * (I12^3) -> 1.7160795 | AJ12: =(A12*1.67262192369E-27 + F12*1.67492749804E-27 + L12*9.1093837015E-31) / 1.6605390666E-27 -> 24.19788 | AM12: =A12 - L12 -> 0 | AN12: =A12-AG12 -> 2.85 | AO12: =4 * PI() * 8.854187817E-12 * (I12 * 0.0000000001)^3 -> 4.558347e-41 | AP12: =AO12 * 10^12 -> 4.558347e-29 | AQ12: =(1 / (2 * 3.14159265358979)) * SQRT((A12 * (1.602176634E-19^2)) / ((AI12 * 1E-30) * 9.1093837015E-31 * 8.8541878128E-12)) -> 2.374289e+16 | AR12: =I12 * 350 -> 259.9467 | AS12: =299792458000000000 / AQ12 -> 12.62662
A13: 13 | B13: Aluminum | C13: Al | D13: Post-transitional Metals | E13: 27 | F13: =E13-A13 -> 14 | G13: =(A13 * 1.007276) + (F13 * 1.008665) + (L13 * 0.00054858) -> 27.22303 | H13: =(G13-(A13*'Atomic Particles'!C1))/'Atomic Particles'!C2+A13 -> 27.007042 | I13: =0.529177210544 * (M13^2 / (A13 - AG13)) -> 0.5039783 | J13: =(('Atomic Particles'!C1)*A13)+(('Atomic Particles'!C2)*Elements!F13) -> 27.215927 | K13: =(E13^(1/3))*Constants!B2 -> 3.75e-15 | L13: 13 | M13: 2 | N13: 2 | O13: 6 | P13: 1 | AF13: 3 | AG13: =IF(A13=1, 0, IF(A13=2, 0.3, IF(A13<=10, 0.35*(N13+O13-1)+0.85*M13, IF(A13<=18, 0.35*(P13+Q13-1)+0.85*(N13+O13)+M13, IF(A13<=36, 0.35*(S13+T13-1)+0.85*(P13+Q13+R13)+(M13+N13+O13), IF(A13<=54, 0.35*(W13+X13-1)+0.85*(S13+T13+U13)+(M13+N13+O13+P13+Q13+R13), IF(A13<=86, 0.35*(AA13+AB13-1)+0.85*(W13+X13+Y13+Z13)+(M13+N13+O13+P13+Q13+R13+S13+T13+U13+V13), IF(A13<=118, 0.35*(AD13+AE13-1)+0.85*(AA13+AB13+AC13)+(M13+N13+O13+P13+Q13+R13+S13+T13+U13+V13+W13+X13+Y13+Z13), 0)))))))) -> 8.8 | AH13: =(G13 * 1.6605E-24) / (AI13 * 1E-24) -> 84.304591 | AI13: =(4/3) * PI() * (I13^3) -> 0.53619667 | AJ13: =(A13*1.67262192369E-27 + F13*1.67492749804E-27 + L13*9.1093837015E-31) / 1.6605390666E-27 -> 27.223034 | AM13: =A13 - L13 -> 0 | AN13: =A13-AG13 -> 4.2 | AO13: =4 * PI() * 8.854187817E-12 * (I13 * 0.0000000001)^3 -> 1.4242758e-41 | AP13: =AO13 * 10^12 -> 1.4242758e-29 | AQ13: =(1 / (2 * 3.14159265358979)) * SQRT((A13 * (1.602176634E-19^2)) / ((AI13 * 1E-30) * 9.1093837015E-31 * 8.8541878128E-12)) -> 4.4210078e+16 | AR13: =I13 * 350 -> 176.3924 | AS13: =299792458000000000 / AQ13 -> 6.7810886
A14: 14 | B14: Silicon | C14: Si | D14: Metalloid | E14: 28 | F14: =E14-A14 -> 14 | G14: =(A14 * 1.007276) + (F14 * 1.008665) + (L14 * 0.00054858) -> 28.230854 | H14: =(G14-(A14*'Atomic Particles'!C1))/'Atomic Particles'!C2+A14 -> 28.007585 | I14: =0.529177210544 * (M14^2 / (A14 - AG14)) -> 0.51005032 | J14: =(('Atomic Particles'!C1)*A14)+(('Atomic Particles'!C2)*Elements!F14) -> 28.223204 | K14: =(E14^(1/3))*Constants!B2 -> 3.7957362e-15 | L14: 14 | M14: 2 | N14: 2 | O14: 6 | P14: 2 | Q14: 2 | AF14: 3 | AG14: =IF(A14=1, 0, IF(A14=2, 0.3, IF(A14<=10, 0.35*(N14+O14-1)+0.85*M14, IF(A14<=18, 0.35*(P14+Q14-1)+0.85*(N14+O14)+M14, IF(A14<=36, 0.35*(S14+T14-1)+0.85*(P14+Q14+R14)+(M14+N14+O14), IF(A14<=54, 0.35*(W14+X14-1)+0.85*(S14+T14+U14)+(M14+N14+O14+P14+Q14+R14), IF(A14<=86, 0.35*(AA14+AB14-1)+0.85*(W14+X14+Y14+Z14)+(M14+N14+O14+P14+Q14+R14+S14+T14+U14+V14), IF(A14<=118, 0.35*(AD14+AE14-1)+0.85*(AA14+AB14+AC14)+(M14+N14+O14+P14+Q14+R14+S14+T14+U14+V14+W14+X14+Y14+Z14), 0)))))))) -> 9.85 | AH14: =(G14 * 1.6605E-24) / (AI14 * 1E-24) -> 84.340313 | AI14: =(4/3) * PI() * (I14^3) -> 0.55581171 | AJ14: =(A14*1.67262192369E-27 + F14*1.67492749804E-27 + L14*9.1093837015E-31) / 1.6605390666E-27 -> 28.230859 | AM14: =A14 - L14 -> 0 | AN14: =A14-AG14 -> 4.15 | AO14: =4 * PI() * 8.854187817E-12 * (I14 * 0.0000000001)^3 -> 1.4763784e-41 | AP14: =AO14 * 10^12 -> 1.4763784e-29 | AQ14: =(1 / (2 * 3.14159265358979)) * SQRT((A14 * (1.602176634E-19^2)) / ((AI14 * 1E-30) * 9.1093837015E-31 * 8.8541878128E-12)) -> 4.5062142e+16 | AR14: =I14 * 350 -> 178.51761 | AS14: =299792458000000000 / AQ14 -> 6.6528674
A15: 15 | B15: Phosphorus | C15: P | D15: Nonmetal | E15: 31 | F15: =E15-A15 -> 16 | G15: =(A15 * 1.007276) + (F15 * 1.008665) + (L15 * 0.00054858) -> 31.256009 | H15: =(G15-(A15*'Atomic Particles'!C1))/'Atomic Particles'!C2+A15 -> 31.008125 | I15: =0.529177210544 * (M15^2 / (A15 - AG15)) -> 0.44098101 | J15: =(('Atomic Particles'!C1)*A15)+(('Atomic Particles'!C2)*Elements!F15) -> 31.247813 | K15: =(E15^(1/3))*Constants!B2 -> 3.9267258e-15 | L15: 15 | M15: 2 | N15: 2 | O15: 6 | P15: 2 | Q15: 3 | AF15: 3 | AG15: =IF(A15=1, 0, IF(A15=2, 0.3, IF(A15<=10, 0.35*(N15+O15-1)+0.85*M15, IF(A15<=18, 0.35*(P15+Q15-1)+0.85*(N15+O15)+M15, IF(A15<=36, 0.35*(S15+T15-1)+0.85*(P15+Q15+R15)+(M15+N15+O15), IF(A15<=54, 0.35*(W15+X15-1)+0.85*(S15+T15+U15)+(M15+N15+O15+P15+Q15+R15), IF(A15<=86, 0.35*(AA15+AB15-1)+0.85*(W15+X15+Y15+Z15)+(M15+N15+O15+P15+Q15+R15+S15+T15+U15+V15), IF(A15<=118, 0.35*(AD15+AE15-1)+0.85*(AA15+AB15+AC15)+(M15+N15+O15+P15+Q15+R15+S15+T15+U15+V15+W15+X15+Y15+Z15), 0)))))))) -> 10.2 | AH15: =(G15 * 1.6605E-24) / (AI15 * 1E-24) -> 144.48545 | AI15: =(4/3) * PI() * (I15^3) -> 0.35920988 | AJ15: =(A15*1.67262192369E-27 + F15*1.67492749804E-27 + L15*9.1093837015E-31) / 1.6605390666E-27 -> 31.256014 | AM15: =A15 - L15 -> 0 | AN15: =A15-AG15 -> 4.8 | AO15: =4 * PI() * 8.854187817E-12 * (I15 * 0.0000000001)^3 -> 9.5415351e-42 | AP15: =AO15 * 10^12 -> 9.5415351e-30 | AQ15: =(1 / (2 * 3.14159265358979)) * SQRT((A15 * (1.602176634E-19^2)) / ((AI15 * 1E-30) * 9.1093837015E-31 * 8.8541878128E-12)) -> 5.8020726e+16 | AR15: =I15 * 350 -> 154.34335 | AS15: =299792458000000000 / AQ15 -> 5.1669891
A16: 16 | B16: Sulfur | C16: S | D16: Nonmetal | E16: 32 | F16: =E16-A16 -> 16 | G16: =(A16 * 1.007276) + (F16 * 1.008665) + (L16 * 0.00054858) -> 32.263833 | H16: =(G16-(A16*'Atomic Particles'!C1))/'Atomic Particles'!C2+A16 -> 32.008668 | I16: =0.529177210544 * (M16^2 / (A16 - AG16)) -> 0.38838694 | J16: =(('Atomic Particles'!C1)*A16)+(('Atomic Particles'!C2)*Elements!F16) -> 32.25509 | K16: =(E16^(1/3))*Constants!B2 -> 3.9685026e-15 | L16: 16 | M16: 2 | N16: 2 | O16: 6 | P16: 2 | Q16: 4 | AF16: 3 | AG16: =IF(A16=1, 0, IF(A16=2, 0.3, IF(A16<=10, 0.35*(N16+O16-1)+0.85*M16, IF(A16<=18, 0.35*(P16+Q16-1)+0.85*(N16+O16)+M16, IF(A16<=36, 0.35*(S16+T16-1)+0.85*(P16+Q16+R16)+(M16+N16+O16), IF(A16<=54, 0.35*(W16+X16-1)+0.85*(S16+T16+U16)+(M16+N16+O16+P16+Q16+R16), IF(A16<=86, 0.35*(AA16+AB16-1)+0.85*(W16+X16+Y16+Z16)+(M16+N16+O16+P16+Q16+R16+S16+T16+U16+V16), IF(A16<=118, 0.35*(AD16+AE16-1)+0.85*(AA16+AB16+AC16)+(M16+N16+O16+P16+Q16+R16+S16+T16+U16+V16+W16+X16+Y16+Z16), 0)))))))) -> 10.55 | AH16: =(G16 * 1.6605E-24) / (AI16 * 1E-24) -> 218.30937 | AI16: =(4/3) * PI() * (I16^3) -> 0.24540447 | AJ16: =(A16*1.67262192369E-27 + F16*1.67492749804E-27 + L16*9.1093837015E-31) / 1.6605390666E-27 -> 32.263839 | AM16: =A16 - L16 -> 0 | AN16: =A16-AG16 -> 5.45 | AO16: =4 * PI() * 8.854187817E-12 * (I16 * 0.0000000001)^3 -> 6.5185719e-42 | AP16: =AO16 * 10^12 -> 6.5185719e-30 | AQ16: =(1 / (2 * 3.14159265358979)) * SQRT((A16 * (1.602176634E-19^2)) / ((AI16 * 1E-30) * 9.1093837015E-31 * 8.8541878128E-12)) -> 7.2498733e+16 | AR16: =I16 * 350 -> 135.93543 | AS16: =299792458000000000 / AQ16 -> 4.1351407
A17: 17 | B17: Chlorine | C17: Cl | D17: Halogen | E17: 37 | F17: =E17-A17 -> 20 | G17: =(A17 * 1.007276) + (F17 * 1.008665) + (L17 * 0.00054858) -> 37.306318 | H17: =(G17-(A17*'Atomic Particles'!C1))/'Atomic Particles'!C2+A17 -> 37.009207 | I17: =0.529177210544 * (M17^2 / (A17 - AG17)) -> 0.34700145 | J17: =(('Atomic Particles'!C1)*A17)+(('Atomic Particles'!C2)*Elements!F17) -> 37.297031 | K17: =(E17^(1/3))*Constants!B2 -> 4.1652773e-15 | L17: 17 | M17: 2 | N17: 2 | O17: 6 | P17: 2 | Q17: 5 | AF17: 3 | AG17: =IF(A17=1, 0, IF(A17=2, 0.3, IF(A17<=10, 0.35*(N17+O17-1)+0.85*M17, IF(A17<=18, 0.35*(P17+Q17-1)+0.85*(N17+O17)+M17, IF(A17<=36, 0.35*(S17+T17-1)+0.85*(P17+Q17+R17)+(M17+N17+O17), IF(A17<=54, 0.35*(W17+X17-1)+0.85*(S17+T17+U17)+(M17+N17+O17+P17+Q17+R17), IF(A17<=86, 0.35*(AA17+AB17-1)+0.85*(W17+X17+Y17+Z17)+(M17+N17+O17+P17+Q17+R17+S17+T17+U17+V17), IF(A17<=118, 0.35*(AD17+AE17-1)+0.85*(AA17+AB17+AC17)+(M17+N17+O17+P17+Q17+R17+S17+T17+U17+V17+W17+X17+Y17+Z17), 0)))))))) -> 10.9 | AH17: =(G17 * 1.6605E-24) / (AI17 * 1E-24) -> 353.94745 | AI17: =(4/3) * PI() * (I17^3) -> 0.1750179 | AJ17: =(A17*1.67262192369E-27 + F17*1.67492749804E-27 + L17*9.1093837015E-31) / 1.6605390666E-27 -> 37.306324 | AM17: =A17 - L17 -> 0 | AN17: =A17-AG17 -> 6.1 | AO17: =4 * PI() * 8.854187817E-12 * (I17 * 0.0000000001)^3 -> 4.6489242e-42 | AP17: =AO17 * 10^12 -> 4.6489242e-30 | AQ17: =(1 / (2 * 3.14159265358979)) * SQRT((A17 * (1.602176634E-19^2)) / ((AI17 * 1E-30) * 9.1093837015E-31 * 8.8541878128E-12)) -> 8.8490141e+16 | AR17: =I17 * 350 -> 121.45051 | AS17: =299792458000000000 / AQ17 -> 3.3878628
A18: 18 | B18: Argon | C18: Ar | D18: Noble Gas | E18: 38 | F18: =E18-A18 -> 20 | G18: =(A18 * 1.007276) + (F18 * 1.008665) + (L18 * 0.00054858) -> 38.314142 | H18: =(G18-(A18*'Atomic Particles'!C1))/'Atomic Particles'!C2+A18 -> 38.00975 | I18: =0.529177210544 * (M18^2 / (A18 - AG18)) -> 0.3135865 | J18: =(('Atomic Particles'!C1)*A18)+(('Atomic Particles'!C2)*Elements!F18) -> 38.304308 | K18: =(E18^(1/3))*Constants!B2 -> 4.2024693e-15 | L18: 18 | M18: 2 | N18: 2 | O18: 6 | P18: 2 | Q18: 6 | AF18: 3 | AG18: =IF(A18=1, 0, IF(A18=2, 0.3, IF(A18<=10, 0.35*(N18+O18-1)+0.85*M18, IF(A18<=18, 0.35*(P18+Q18-1)+0.85*(N18+O18)+M18, IF(A18<=36, 0.35*(S18+T18-1)+0.85*(P18+Q18+R18)+(M18+N18+O18), IF(A18<=54, 0.35*(W18+X18-1)+0.85*(S18+T18+U18)+(M18+N18+O18+P18+Q18+R18), IF(A18<=86, 0.35*(AA18+AB18-1)+0.85*(W18+X18+Y18+Z18)+(M18+N18+O18+P18+Q18+R18+S18+T18+U18+V18), IF(A18<=118, 0.35*(AD18+AE18-1)+0.85*(AA18+AB18+AC18)+(M18+N18+O18+P18+Q18+R18+S18+T18+U18+V18+W18+X18+Y18+Z18), 0)))))))) -> 11.25 | AH18: =(G18 * 1.6605E-24) / (AI18 * 1E-24) -> 492.53526 | AI18: =(4/3) * PI() * (I18^3) -> 0.1291697 | AJ18: =(A18*1.67262192369E-27 + F18*1.67492749804E-27 + L18*9.1093837015E-31) / 1.6605390666E-27 -> 38.314149 | AM18: =A18 - L18 -> 0 | AN18: =A18-AG18 -> 6.75 | AO18: =4 * PI() * 8.854187817E-12 * (I18 * 0.0000000001)^3 -> 3.4310784e-42 | AP18: =AO18 * 10^12 -> 3.4310784e-30 | AQ18: =(1 / (2 * 3.14159265358979)) * SQRT((A18 * (1.602176634E-19^2)) / ((AI18 * 1E-30) * 9.1093837015E-31 * 8.8541878128E-12)) -> 1.0599066e+17 | AR18: =I18 * 350 -> 109.75527 | AS18: =299792458000000000 / AQ18 -> 2.82848
A19: 19 | B19: Potassium | C19: K | D19: Alkali Metal | E19: 39 | F19: =E19-A19 -> 20 | G19: =(A19 * 1.007276) + (F19 * 1.008665) + (L19 * 0.00054858) -> 39.321967 | H19: =(G19-(A19*'Atomic Particles'!C1))/'Atomic Particles'!C2+A19 -> 39.010292 | I19: =0.529177210544 * (M19^2 / (A19 - AG19)) -> 0.96214038 | J19: =(('Atomic Particles'!C1)*A19)+(('Atomic Particles'!C2)*Elements!F19) -> 39.311585 | K19: =(E19^(1/3))*Constants!B2 -> 4.2390143e-15 | L19: 19 | M19: 2 | N19: 2 | O19: 6 | P19: 2 | Q19: 6 | S19: 1 | AF19: 4 | AG19: =IF(A19=1, 0, IF(A19=2, 0.3, IF(A19<=10, 0.35*(N19+O19-1)+0.85*M19, IF(A19<=18, 0.35*(P19+Q19-1)+0.85*(N19+O19)+M19, IF(A19<=36, 0.35*(S19+T19-1)+0.85*(P19+Q19+R19)+(M19+N19+O19), IF(A19<=54, 0.35*(W19+X19-1)+0.85*(S19+T19+U19)+(M19+N19+O19+P19+Q19+R19), IF(A19<=86, 0.35*(AA19+AB19-1)+0.85*(W19+X19+Y19+Z19)+(M19+N19+O19+P19+Q19+R19+S19+T19+U19+V19), IF(A19<=118, 0.35*(AD19+AE19-1)+0.85*(AA19+AB19+AC19)+(M19+N19+O19+P19+Q19+R19+S19+T19+U19+V19+W19+X19+Y19+Z19), 0)))))))) -> 16.8 | AH19: =(G19 * 1.6605E-24) / (AI19 * 1E-24) -> 17.501295 | AI19: =(4/3) * PI() * (I19^3) -> 3.7308169 | AJ19: =(A19*1.67262192369E-27 + F19*1.67492749804E-27 + L19*9.1093837015E-31) / 1.6605390666E-27 -> 39.321974 | AM19: =A19 - L19 -> 0 | AN19: =A19-AG19 -> 2.2 | AO19: =4 * PI() * 8.854187817E-12 * (I19 * 0.0000000001)^3 -> 9.9100061e-41 | AP19: =AO19 * 10^12 -> 9.9100061e-29 | AQ19: =(1 / (2 * 3.14159265358979)) * SQRT((A19 * (1.602176634E-19^2)) / ((AI19 * 1E-30) * 9.1093837015E-31 * 8.8541878128E-12)) -> 2.0262195e+16 | AR19: =I19 * 350 -> 336.74913 | AS19: =299792458000000000 / AQ19 -> 14.795655
A20: 20 | B20: Calcium | C20: Ca | D20: Alkali Earth Metal | E20: 42 | F20: =E20-A20 -> 22 | G20: =(A20 * 1.007276) + (F20 * 1.008665) + (L20 * 0.00054858) -> 42.347122 | H20: =(G20-(A20*'Atomic Particles'!C1))/'Atomic Particles'!C2+A20 -> 42.010833 | I20: =0.529177210544 * (M20^2 / (A20 - AG20)) -> 0.74270486 | J20: =(('Atomic Particles'!C1)*A20)+(('Atomic Particles'!C2)*Elements!F20) -> 42.336194 | K20: =(E20^(1/3))*Constants!B2 -> 4.3450333e-15 | L20: 20 | M20: 2 | N20: 2 | O20: 6 | P20: 2 | Q20: 6 | S20: 2 | AF20: 4 | AG20: =IF(A20=1, 0, IF(A20=2, 0.3, IF(A20<=10, 0.35*(N20+O20-1)+0.85*M20, IF(A20<=18, 0.35*(P20+Q20-1)+0.85*(N20+O20)+M20, IF(A20<=36, 0.35*(S20+T20-1)+0.85*(P20+Q20+R20)+(M20+N20+O20), IF(A20<=54, 0.35*(W20+X20-1)+0.85*(S20+T20+U20)+(M20+N20+O20+P20+Q20+R20), IF(A20<=86, 0.35*(AA20+AB20-1)+0.85*(W20+X20+Y20+Z20)+(M20+N20+O20+P20+Q20+R20+S20+T20+U20+V20), IF(A20<=118, 0.35*(AD20+AE20-1)+0.85*(AA20+AB20+AC20)+(M20+N20+O20+P20+Q20+R20+S20+T20+U20+V20+W20+X20+Y20+Z20), 0)))))))) -> 17.15 | AH20: =(G20 * 1.6605E-24) / (AI20 * 1E-24) -> 40.975605 | AI20: =(4/3) * PI() * (I20^3) -> 1.7160795 | AJ20: =(A20*1.67262192369E-27 + F20*1.67492749804E-27 + L20*9.1093837015E-31) / 1.6605390666E-27 -> 42.347129 | AM20: =A20 - L20 -> 0 | AN20: =A20-AG20 -> 2.85 | AO20: =4 * PI() * 8.854187817E-12 * (I20 * 0.0000000001)^3 -> 4.558347e-41 | AP20: =AO20 * 10^12 -> 4.558347e-29 | AQ20: =(1 / (2 * 3.14159265358979)) * SQRT((A20 * (1.602176634E-19^2)) / ((AI20 * 1E-30) * 9.1093837015E-31 * 8.8541878128E-12)) -> 3.065194e+16 | AR20: =I20 * 350 -> 259.9467 | AS20: =299792458000000000 / AQ20 -> 9.780538
A21: 21 | B21: Scandium | C21: Sc | D21: Transition Metals | E21: 45 | F21: =E21-A21 -> 24 | G21: =(A21 * 1.007276) + (F21 * 1.008665) + (L21 * 0.00054858) -> 45.372276 | H21: =(G21-(A21*'Atomic Particles'!C1))/'Atomic Particles'!C2+A21 -> 45.011374 | I21: =0.529177210544 * (M21^2 / (A21 - AG21)) -> 0.5497945 | J21: =(('Atomic Particles'!C1)*A21)+(('Atomic Particles'!C2)*Elements!F21) -> 45.360804 | K21: =(E21^(1/3))*Constants!B2 -> 4.4461166e-15 | L21: 21 | M21: 2 | N21: 2 | O21: 6 | P21: 2 | Q21: 6 | S21: 2 | AF21: 4 | AG21: =IF(A21=1, 0, IF(A21=2, 0.3, IF(A21<=10, 0.35*(N21+O21-1)+0.85*M21, IF(A21<=18, 0.35*(P21+Q21-1)+0.85*(N21+O21)+M21, IF(A21<=36, 0.35*(S21+T21-1)+0.85*(P21+Q21+R21)+(M21+N21+O21), IF(A21<=54, 0.35*(W21+X21-1)+0.85*(S21+T21+U21)+(M21+N21+O21+P21+Q21+R21), IF(A21<=86, 0.35*(AA21+AB21-1)+0.85*(W21+X21+Y21+Z21)+(M21+N21+O21+P21+Q21+R21+S21+T21+U21+V21), IF(A21<=118, 0.35*(AD21+AE21-1)+0.85*(AA21+AB21+AC21)+(M21+N21+O21+P21+Q21+R21+S21+T21+U21+V21+W21+X21+Y21+Z21), 0)))))))) -> 17.15 | AH21: =(G21 * 1.6605E-24) / (AI21 * 1E-24) -> 108.22801 | AI21: =(4/3) * PI() * (I21^3) -> 0.69612911 | AJ21: =(A21*1.67262192369E-27 + F21*1.67492749804E-27 + L21*9.1093837015E-31) / 1.6605390666E-27 -> 45.372284 | AM21: =A21 - L21 -> 0 | AN21: =A21-AG21 -> 3.85 | AO21: =4 * PI() * 8.854187817E-12 * (I21 * 0.0000000001)^3 -> 1.8490974e-41 | AP21: =AO21 * 10^12 -> 1.8490974e-29 | AQ21: =(1 / (2 * 3.14159265358979)) * SQRT((A21 * (1.602176634E-19^2)) / ((AI21 * 1E-30) * 9.1093837015E-31 * 8.8541878128E-12)) -> 4.9314702e+16 | AR21: =I21 * 350 -> 192.42808 | AS21: =299792458000000000 / AQ21 -> 6.07917
A22: 22 | B22: Titanium | C22: Ti | D22: Transition Metals | E22: 49 | F22: =E22-A22 -> 27 | G22: =(A22 * 1.007276) + (F22 * 1.008665) + (L22 * 0.00054858) -> 49.406096 | H22: =(G22-(A22*'Atomic Particles'!C1))/'Atomic Particles'!C2+A22 -> 49.011914 | I22: =0.529177210544 * (M22^2 / (A22 - AG22)) -> 0.67197106 | J22: =(('Atomic Particles'!C1)*A22)+(('Atomic Particles'!C2)*Elements!F22) -> 49.394079 | K22: =(E22^(1/3))*Constants!B2 -> 4.5741321e-15 | L22: 22 | M22: 2 | N22: 2 | O22: 6 | P22: 2 | Q22: 6 | R22: 2 | S22: 2 | AF22: 4 | AG22: =IF(A22=1, 0, IF(A22=2, 0.3, IF(A22<=10, 0.35*(N22+O22-1)+0.85*M22, IF(A22<=18, 0.35*(P22+Q22-1)+0.85*(N22+O22)+M22, IF(A22<=36, 0.35*(S22+T22-1)+0.85*(P22+Q22+R22)+(M22+N22+O22), IF(A22<=54, 0.35*(W22+X22-1)+0.85*(S22+T22+U22)+(M22+N22+O22+P22+Q22+R22), IF(A22<=86, 0.35*(AA22+AB22-1)+0.85*(W22+X22+Y22+Z22)+(M22+N22+O22+P22+Q22+R22+S22+T22+U22+V22), IF(A22<=118, 0.35*(AD22+AE22-1)+0.85*(AA22+AB22+AC22)+(M22+N22+O22+P22+Q22+R22+S22+T22+U22+V22+W22+X22+Y22+Z22), 0)))))))) -> 18.85 | AH22: =(G22 * 1.6605E-24) / (AI22 * 1E-24) -> 64.547451 | AI22: =(4/3) * PI() * (I22^3) -> 1.2709847 | AJ22: =(A22*1.67262192369E-27 + F22*1.67492749804E-27 + L22*9.1093837015E-31) / 1.6605390666E-27 -> 49.406104 | AM22: =A22 - L22 -> 0 | AN22: =A22-AG22 -> 3.15 | AO22: =4 * PI() * 8.854187817E-12 * (I22 * 0.0000000001)^3 -> 3.3760612e-41 | AP22: =AO22 * 10^12 -> 3.3760612e-29 | AQ22: =(1 / (2 * 3.14159265358979)) * SQRT((A22 * (1.602176634E-19^2)) / ((AI22 * 1E-30) * 9.1093837015E-31 * 8.8541878128E-12)) -> 3.7355353e+16 | AR22: =I22 * 350 -> 235.18987 | AS22: =299792458000000000 / AQ22 -> 8.0254217
A23: 23 | B23: Vanadium | C23: V | D23: Transition Metals | E23: 51 | F23: =E23-A23 -> 28 | G23: =(A23 * 1.007276) + (F23 * 1.008665) + (L23 * 0.00054858) -> 51.422585 | H23: =(G23-(A23*'Atomic Particles'!C1))/'Atomic Particles'!C2+A23 -> 51.012456 | I23: =0.529177210544 * (M23^2 / (A23 - AG23)) -> 0.64142692 | J23: =(('Atomic Particles'!C23)*A1)+(('Atomic Particles'!C2)*Elements!F23) -> 28.242646 | K23: =(E23^(1/3))*Constants!B2 -> 4.6355372e-15 | L23: 23 | M23: 2 | N23: 2 | O23: 6 | P23: 2 | Q23: 6 | R23: 3 | S23: 2 | AF23: 4 | AG23: =IF(A23=1, 0, IF(A23=2, 0.3, IF(A23<=10, 0.35*(N23+O23-1)+0.85*M23, IF(A23<=18, 0.35*(P23+Q23-1)+0.85*(N23+O23)+M23, IF(A23<=36, 0.35*(S23+T23-1)+0.85*(P23+Q23+R23)+(M23+N23+O23), IF(A23<=54, 0.35*(W23+X23-1)+0.85*(S23+T23+U23)+(M23+N23+O23+P23+Q23+R23), IF(A23<=86, 0.35*(AA23+AB23-1)+0.85*(W23+X23+Y23+Z23)+(M23+N23+O23+P23+Q23+R23+S23+T23+U23+V23), IF(A23<=118, 0.35*(AD23+AE23-1)+0.85*(AA23+AB23+AC23)+(M23+N23+O23+P23+Q23+R23+S23+T23+U23+V23+W23+X23+Y23+Z23), 0)))))))) -> 19.7 | AH23: =(G23 * 1.6605E-24) / (AI23 * 1E-24) -> 77.243621 | AI23: =(4/3) * PI() * (I23^3) -> 1.1054272 | AJ23: =(A23*1.67262192369E-27 + F23*1.67492749804E-27 + L23*9.1093837015E-31) / 1.6605390666E-27 -> 51.422594 | AM23: =A23 - L23 -> 0 | AN23: =A23-AG23 -> 3.3 | AO23: =4 * PI() * 8.854187817E-12 * (I23 * 0.0000000001)^3 -> 2.9362981e-41 | AP23: =AO23 * 10^12 -> 2.9362981e-29 | AQ23: =(1 / (2 * 3.14159265358979)) * SQRT((A23 * (1.602176634E-19^2)) / ((AI23 * 1E-30) * 9.1093837015E-31 * 8.8541878128E-12)) -> 4.0955337e+16 | AR23: =I23 * 350 -> 224.49942 | AS23: =299792458000000000 / AQ23 -> 7.3199852
A24: 24 | B24: Chromium | C24: Cr | D24: Transition Metals | E24: 52 | F24: =E24-A24 -> 28 | G24: =(A24 * 1.007276) + (F24 * 1.008665) + (L24 * 0.00054858) -> 52.43041 | H24: =(G24-(A24*'Atomic Particles'!C1))/'Atomic Particles'!C2+A24 -> 52.012998 | I24: =0.529177210544 * (M24^2 / (A24 - AG24)) -> 0.71752842 | J24: =(('Atomic Particles'!C1)*A24)+(('Atomic Particles'!C2)*Elements!F24) -> 52.417299 | K24: =(E24^(1/3))*Constants!B2 -> 4.6656389e-15 | L24: 24 | M24: 2 | N24: 2 | O24: 6 | P24: 2 | Q24: 6 | R24: 5 | S24: 1 | AF24: 4 | AG24: =IF(A24=1, 0, IF(A24=2, 0.3, IF(A24<=10, 0.35*(N24+O24-1)+0.85*M24, IF(A24<=18, 0.35*(P24+Q24-1)+0.85*(N24+O24)+M24, IF(A24<=36, 0.35*(S24+T24-1)+0.85*(P24+Q24+R24)+(M24+N24+O24), IF(A24<=54, 0.35*(W24+X24-1)+0.85*(S24+T24+U24)+(M24+N24+O24+P24+Q24+R24), IF(A24<=86, 0.35*(AA24+AB24-1)+0.85*(W24+X24+Y24+Z24)+(M24+N24+O24+P24+Q24+R24+S24+T24+U24+V24), IF(A24<=118, 0.35*(AD24+AE24-1)+0.85*(AA24+AB24+AC24)+(M24+N24+O24+P24+Q24+R24+S24+T24+U24+V24+W24+X24+Y24+Z24), 0)))))))) -> 21.05 | AH24: =(G24 * 1.6605E-24) / (AI24 * 1E-24) -> 56.262134 | AI24: =(4/3) * PI() * (I24^3) -> 1.5474119 | AJ24: =(A24*1.67262192369E-27 + F24*1.67492749804E-27 + L24*9.1093837015E-31) / 1.6605390666E-27 -> 52.430419 | AM24: =A24 - L24 -> 0 | AN24: =A24-AG24 -> 2.95 | AO24: =4 * PI() * 8.854187817E-12 * (I24 * 0.0000000001)^3 -> 4.1103227e-41 | AP24: =AO24 * 10^12 -> 4.1103227e-29 | AQ24: =(1 / (2 * 3.14159265358979)) * SQRT((A24 * (1.602176634E-19^2)) / ((AI24 * 1E-30) * 9.1093837015E-31 * 8.8541878128E-12)) -> 3.5360168e+16 | AR24: =I24 * 350 -> 251.13495 | AS24: =299792458000000000 / AQ24 -> 8.4782533
A25: 25 | B25: Manganese | C25: Mn | D25: Transition Metals | E25: 55 | F25: =E25-A25 -> 30 | G25: =(A25 * 1.007276) + (F25 * 1.008665) + (L25 * 0.00054858) -> 55.455565 | H25: =(G25-(A25*'Atomic Particles'!C1))/'Atomic Particles'!C2+A25 -> 55.013539 | I25: =0.529177210544 * (M25^2 / (A25 - AG25)) -> 0.58797468 | J25: =(('Atomic Particles'!C1)*A25)+(('Atomic Particles'!C2)*Elements!F25) -> 55.441908 | K25: =(E25^(1/3))*Constants!B2 -> 4.7536906e-15 | L25: 25 | M25: 2 | N25: 2 | O25: 6 | P25: 2 | Q25: 6 | R25: 5 | S25: 2 | AF25: 4 | AG25: =IF(A25=1, 0, IF(A25=2, 0.3, IF(A25<=10, 0.35*(N25+O25-1)+0.85*M25, IF(A25<=18, 0.35*(P25+Q25-1)+0.85*(N25+O25)+M25, IF(A25<=36, 0.35*(S25+T25-1)+0.85*(P25+Q25+R25)+(M25+N25+O25), IF(A25<=54, 0.35*(W25+X25-1)+0.85*(S25+T25+U25)+(M25+N25+O25+P25+Q25+R25), IF(A25<=86, 0.35*(AA25+AB25-1)+0.85*(W25+X25+Y25+Z25)+(M25+N25+O25+P25+Q25+R25+S25+T25+U25+V25), IF(A25<=118, 0.35*(AD25+AE25-1)+0.85*(AA25+AB25+AC25)+(M25+N25+O25+P25+Q25+R25+S25+T25+U25+V25+W25+X25+Y25+Z25), 0)))))))) -> 21.4 | AH25: =(G25 * 1.6605E-24) / (AI25 * 1E-24) -> 108.14826 | AI25: =(4/3) * PI() * (I25^3) -> 0.85146045 | AJ25: =(A25*1.67262192369E-27 + F25*1.67492749804E-27 + L25*9.1093837015E-31) / 1.6605390666E-27 -> 55.455574 | AM25: =A25 - L25 -> 0 | AN25: =A25-AG25 -> 3.6 | AO25: =4 * PI() * 8.854187817E-12 * (I25 * 0.0000000001)^3 -> 2.2616972e-41 | AP25: =AO25 * 10^12 -> 2.2616972e-29 | AQ25: =(1 / (2 * 3.14159265358979)) * SQRT((A25 * (1.602176634E-19^2)) / ((AI25 * 1E-30) * 9.1093837015E-31 * 8.8541878128E-12)) -> 4.8651858e+16 | AR25: =I25 * 350 -> 205.79114 | AS25: =299792458000000000 / AQ25 -> 6.1619941
A26: 26 | B26: Iron | C26: Fe | D26: Transition Metals | E26: 56 | F26: =E26-A26 -> 30 | G26: =(A26 * 1.007276) + (F26 * 1.008665) + (L26 * 0.00054858) -> 56.463389 | H26: =(G26-(A26*'Atomic Particles'!C1))/'Atomic Particles'!C2+A26 -> 56.014082 | I26: =0.529177210544 * (M26^2 / (A26 - AG26)) -> 0.56445569 | J26: =(('Atomic Particles'!C1)*A26)+(('Atomic Particles'!C2)*Elements!F26) -> 56.449185 | K26: =(E26^(1/3))*Constants!B2 -> 4.782328e-15 | L26: 26 | M26: 2 | N26: 2 | O26: 6 | P26: 2 | Q26: 6 | R26: 6 | S26: 2 | AF26: 4 | AG26: =IF(A26=1, 0, IF(A26=2, 0.3, IF(A26<=10, 0.35*(N26+O26-1)+0.85*M26, IF(A26<=18, 0.35*(P26+Q26-1)+0.85*(N26+O26)+M26, IF(A26<=36, 0.35*(S26+T26-1)+0.85*(P26+Q26+R26)+(M26+N26+O26), IF(A26<=54, 0.35*(W26+X26-1)+0.85*(S26+T26+U26)+(M26+N26+O26+P26+Q26+R26), IF(A26<=86, 0.35*(AA26+AB26-1)+0.85*(W26+X26+Y26+Z26)+(M26+N26+O26+P26+Q26+R26+S26+T26+U26+V26), IF(A26<=118, 0.35*(AD26+AE26-1)+0.85*(AA26+AB26+AC26)+(M26+N26+O26+P26+Q26+R26+S26+T26+U26+V26+W26+X26+Y26+Z26), 0)))))))) -> 22.25 | AH26: =(G26 * 1.6605E-24) / (AI26 * 1E-24) -> 124.45938 | AI26: =(4/3) * PI() * (I26^3) -> 0.75331771 | AJ26: =(A26*1.67262192369E-27 + F26*1.67492749804E-27 + L26*9.1093837015E-31) / 1.6605390666E-27 -> 56.463399 | AM26: =A26 - L26 -> 0 | AN26: =A26-AG26 -> 3.75 | AO26: =4 * PI() * 8.854187817E-12 * (I26 * 0.0000000001)^3 -> 2.0010049e-41 | AP26: =AO26 * 10^12 -> 2.0010049e-29 | AQ26: =(1 / (2 * 3.14159265358979)) * SQRT((A26 * (1.602176634E-19^2)) / ((AI26 * 1E-30) * 9.1093837015E-31 * 8.8541878128E-12)) -> 5.2748395e+16 | AR26: =I26 * 350 -> 197.55949 | AS26: =299792458000000000 / AQ26 -> 5.6834423
A27: 27 | B27: Cobalt | C27: Co | D27: Transition Metals | E27: 59 | F27: =E27-A27 -> 32 | G27: =(A27 * 1.007276) + (F27 * 1.008665) + (L27 * 0.00054858) -> 59.488544 | H27: =(G27-(A27*'Atomic Particles'!C1))/'Atomic Particles'!C2+A27 -> 59.014623 | I27: =0.529177210544 * (M27^2 / (A27 - AG27)) -> 0.54274586 | J27: =(('Atomic Particles'!C1)*A27)+(('Atomic Particles'!C2)*Elements!F27) -> 59.473794 | K27: =(E27^(1/3))*Constants!B2 -> 4.8662455e-15 | L27: 27 | M27: 2 | N27: 2 | O27: 6 | P27: 2 | Q27: 6 | R27: 7 | S27: 2 | AF27: 4 | AG27: =IF(A27=1, 0, IF(A27=2, 0.3, IF(A27<=10, 0.35*(N27+O27-1)+0.85*M27, IF(A27<=18, 0.35*(P27+Q27-1)+0.85*(N27+O27)+M27, IF(A27<=36, 0.35*(S27+T27-1)+0.85*(P27+Q27+R27)+(M27+N27+O27), IF(A27<=54, 0.35*(W27+X27-1)+0.85*(S27+T27+U27)+(M27+N27+O27+P27+Q27+R27), IF(A27<=86, 0.35*(AA27+AB27-1)+0.85*(W27+X27+Y27+Z27)+(M27+N27+O27+P27+Q27+R27+S27+T27+U27+V27), IF(A27<=118, 0.35*(AD27+AE27-1)+0.85*(AA27+AB27+AC27)+(M27+N27+O27+P27+Q27+R27+S27+T27+U27+V27+W27+X27+Y27+Z27), 0)))))))) -> 23.1 | AH27: =(G27 * 1.6605E-24) / (AI27 * 1E-24) -> 147.50069 | AI27: =(4/3) * PI() * (I27^3) -> 0.6696967 | AJ27: =(A27*1.67262192369E-27 + F27*1.67492749804E-27 + L27*9.1093837015E-31) / 1.6605390666E-27 -> 59.488554 | AM27: =A27 - L27 -> 0 | AN27: =A27-AG27 -> 3.9 | AO27: =4 * PI() * 8.854187817E-12 * (I27 * 0.0000000001)^3 -> 1.7788861e-41 | AP27: =AO27 * 10^12 -> 1.7788861e-29 | AQ27: =(1 / (2 * 3.14159265358979)) * SQRT((A27 * (1.602176634E-19^2)) / ((AI27 * 1E-30) * 9.1093837015E-31 * 8.8541878128E-12)) -> 5.7010449e+16 | AR27: =I27 * 350 -> 189.96105 | AS27: =299792458000000000 / AQ27 -> 5.2585528
A28: 28 | B28: Nickel | C28: Ni | D28: Transition Metals | E28: 60 | F28: =E28-A28 -> 32 | G28: =(A28 * 1.007276) + (F28 * 1.008665) + (L28 * 0.00054858) -> 60.496368 | H28: =(G28-(A28*'Atomic Particles'!C1))/'Atomic Particles'!C2+A28 -> 60.015165 | I28: =0.529177210544 * (M28^2 / (A28 - AG28)) -> 0.52264416 | J28: =(('Atomic Particles'!C1)*A28)+(('Atomic Particles'!C2)*Elements!F28) -> 60.481071 | K28: =(E28^(1/3))*Constants!B2 -> 4.8935846e-15 | L28: 28 | M28: 2 | N28: 2 | O28: 6 | P28: 2 | Q28: 6 | R28: 8 | S28: 2 | AF28: 4 | AG28: =IF(A28=1, 0, IF(A28=2, 0.3, IF(A28<=10, 0.35*(N28+O28-1)+0.85*M28, IF(A28<=18, 0.35*(P28+Q28-1)+0.85*(N28+O28)+M28, IF(A28<=36, 0.35*(S28+T28-1)+0.85*(P28+Q28+R28)+(M28+N28+O28), IF(A28<=54, 0.35*(W28+X28-1)+0.85*(S28+T28+U28)+(M28+N28+O28+P28+Q28+R28), IF(A28<=86, 0.35*(AA28+AB28-1)+0.85*(W28+X28+Y28+Z28)+(M28+N28+O28+P28+Q28+R28+S28+T28+U28+V28), IF(A28<=118, 0.35*(AD28+AE28-1)+0.85*(AA28+AB28+AC28)+(M28+N28+O28+P28+Q28+R28+S28+T28+U28+V28+W28+X28+Y28+Z28), 0)))))))) -> 23.95 | AH28: =(G28 * 1.6605E-24) / (AI28 * 1E-24) -> 167.98143 | AI28: =(4/3) * PI() * (I28^3) -> 0.59800789 | AJ28: =(A28*1.67262192369E-27 + F28*1.67492749804E-27 + L28*9.1093837015E-31) / 1.6605390666E-27 -> 60.496379 | AM28: =A28 - L28 -> 0 | AN28: =A28-AG28 -> 4.05 | AO28: =4 * PI() * 8.854187817E-12 * (I28 * 0.0000000001)^3 -> 1.5884622e-41 | AP28: =AO28 * 10^12 -> 1.5884622e-29 | AQ28: =(1 / (2 * 3.14159265358979)) * SQRT((A28 * (1.602176634E-19^2)) / ((AI28 * 1E-30) * 9.1093837015E-31 * 8.8541878128E-12)) -> 6.1438022e+16 | AR28: =I28 * 350 -> 182.92546 | AS28: =299792458000000000 / AQ28 -> 4.8795917
A29: 29 | B29: Copper | C29: Cu | D29: Transition Metals | E29: 63 | F29: =E29-A29 -> 34 | G29: =(A29 * 1.007276) + (F29 * 1.008665) + (L29 * 0.00054858) -> 63.521523 | H29: =(G29-(A29*'Atomic Particles'!C1))/'Atomic Particles'!C2+A29 -> 63.015706 | I29: =0.529177210544 * (M29^2 / (A29 - AG29)) -> 0.57208347 | J29: =(('Atomic Particles'!C1)*A29)+(('Atomic Particles'!C2)*Elements!F29) -> 63.50568 | K29: =(E29^(1/3))*Constants!B2 -> 4.9738215e-15 | L29: 29 | M29: 2 | N29: 2 | O29: 6 | P29: 2 | Q29: 6 | R29: 10 | S29: 1 | AF29: 4 | AG29: =IF(A29=1, 0, IF(A29=2, 0.3, IF(A29<=10, 0.35*(N29+O29-1)+0.85*M29, IF(A29<=18, 0.35*(P29+Q29-1)+0.85*(N29+O29)+M29, IF(A29<=36, 0.35*(S29+T29-1)+0.85*(P29+Q29+R29)+(M29+N29+O29), IF(A29<=54, 0.35*(W29+X29-1)+0.85*(S29+T29+U29)+(M29+N29+O29+P29+Q29+R29), IF(A29<=86, 0.35*(AA29+AB29-1)+0.85*(W29+X29+Y29+Z29)+(M29+N29+O29+P29+Q29+R29+S29+T29+U29+V29), IF(A29<=118, 0.35*(AD29+AE29-1)+0.85*(AA29+AB29+AC29)+(M29+N29+O29+P29+Q29+R29+S29+T29+U29+V29+W29+X29+Y29+Z29), 0)))))))) -> 25.3 | AH29: =(G29 * 1.6605E-24) / (AI29 * 1E-24) -> 134.49092 | AI29: =(4/3) * PI() * (I29^3) -> 0.78427218 | AJ29: =(A29*1.67262192369E-27 + F29*1.67492749804E-27 + L29*9.1093837015E-31) / 1.6605390666E-27 -> 63.521533 | AM29: =A29 - L29 -> 0 | AN29: =A29-AG29 -> 3.7 | AO29: =4 * PI() * 8.854187817E-12 * (I29 * 0.0000000001)^3 -> 2.083228e-41 | AP29: =AO29 * 10^12 -> 2.083228e-29 | AQ29: =(1 / (2 * 3.14159265358979)) * SQRT((A29 * (1.602176634E-19^2)) / ((AI29 * 1E-30) * 9.1093837015E-31 * 8.8541878128E-12)) -> 5.4598066e+16 | AR29: =I29 * 350 -> 200.22921 | AS29: =299792458000000000 / AQ29 -> 5.4908989
A30: 30 | B30: Zinc | C30: Zn | D30: Transition Metals | E30: 64 | F30: =E30-A30 -> 34 | G30: =(A30 * 1.007276) + (F30 * 1.008665) + (L30 * 0.00054858) -> 64.529347 | H30: =(G30-(A30*'Atomic Particles'!C1))/'Atomic Particles'!C2+A30 -> 64.016249 | I30: =0.529177210544 * (M30^2 / (A30 - AG30)) -> 0.48659973 | J30: =(('Atomic Particles'!C1)*A30)+(('Atomic Particles'!C2)*Elements!F30) -> 64.512958 | K30: =(E30^(1/3))*Constants!B2 -> 5e-15 | L30: 30 | M30: 2 | N30: 2 | O30: 6 | P30: 2 | Q30: 6 | R30: 10 | S30: 2 | AF30: 4 | AG30: =IF(A30=1, 0, IF(A30=2, 0.3, IF(A30<=10, 0.35*(N30+O30-1)+0.85*M30, IF(A30<=18, 0.35*(P30+Q30-1)+0.85*(N30+O30)+M30, IF(A30<=36, 0.35*(S30+T30-1)+0.85*(P30+Q30+R30)+(M30+N30+O30), IF(A30<=54, 0.35*(W30+X30-1)+0.85*(S30+T30+U30)+(M30+N30+O30+P30+Q30+R30), IF(A30<=86, 0.35*(AA30+AB30-1)+0.85*(W30+X30+Y30+Z30)+(M30+N30+O30+P30+Q30+R30+S30+T30+U30+V30), IF(A30<=118, 0.35*(AD30+AE30-1)+0.85*(AA30+AB30+AC30)+(M30+N30+O30+P30+Q30+R30+S30+T30+U30+V30+W30+X30+Y30+Z30), 0)))))))) -> 25.65 | AH30: =(G30 * 1.6605E-24) / (AI30 * 1E-24) -> 222.01992 | AI30: =(4/3) * PI() * (I30^3) -> 0.48261877 | AJ30: =(A30*1.67262192369E-27 + F30*1.67492749804E-27 + L30*9.1093837015E-31) / 1.6605390666E-27 -> 64.529359 | AM30: =A30 - L30 -> 0 | AN30: =A30-AG30 -> 4.35 | AO30: =4 * PI() * 8.854187817E-12 * (I30 * 0.0000000001)^3 -> 1.2819592e-41 | AP30: =AO30 * 10^12 -> 1.2819592e-29 | AQ30: =(1 / (2 * 3.14159265358979)) * SQRT((A30 * (1.602176634E-19^2)) / ((AI30 * 1E-30) * 9.1093837015E-31 * 8.8541878128E-12)) -> 7.0789718e+16 | AR30: =I30 * 350 -> 170.30991 | AS30: =299792458000000000 / AQ30 -> 4.2349718
A31: 31 | B31: Gallium | C31: Ga | D31: Post-transitional Metals | E31: 71 | F31: =E31-A31 -> 40 | G31: =(A31 * 1.007276) + (F31 * 1.008665) + (L31 * 0.00054858) -> 71.589162 | H31: =(G31-(A31*'Atomic Particles'!C1))/'Atomic Particles'!C2+A31 -> 71.016786 | I31: =0.529177210544 * (M31^2 / (A31 - AG31)) -> 0.42334177 | J31: =(('Atomic Particles'!C1)*A31)+(('Atomic Particles'!C2)*Elements!F31) -> 71.57223 | K31: =(E31^(1/3))*Constants!B2 -> 5.1760222e-15 | L31: 31 | M31: 2 | N31: 2 | O31: 6 | P31: 2 | Q31: 6 | R31: 10 | S31: 2 | T31: 1 | AF31: 4 | AG31: =IF(A31=1, 0, IF(A31=2, 0.3, IF(A31<=10, 0.35*(N31+O31-1)+0.85*M31, IF(A31<=18, 0.35*(P31+Q31-1)+0.85*(N31+O31)+M31, IF(A31<=36, 0.35*(S31+T31-1)+0.85*(P31+Q31+R31)+(M31+N31+O31), IF(A31<=54, 0.35*(W31+X31-1)+0.85*(S31+T31+U31)+(M31+N31+O31+P31+Q31+R31), IF(A31<=86, 0.35*(AA31+AB31-1)+0.85*(W31+X31+Y31+Z31)+(M31+N31+O31+P31+Q31+R31+S31+T31+U31+V31), IF(A31<=118, 0.35*(AD31+AE31-1)+0.85*(AA31+AB31+AC31)+(M31+N31+O31+P31+Q31+R31+S31+T31+U31+V31+W31+X31+Y31+Z31), 0)))))))) -> 26 | AH31: =(G31 * 1.6605E-24) / (AI31 * 1E-24) -> 374.04529 | AI31: =(4/3) * PI() * (I31^3) -> 0.31780591 | AJ31: =(A31*1.67262192369E-27 + F31*1.67492749804E-27 + L31*9.1093837015E-31) / 1.6605390666E-27 -> 71.589173 | AM31: =A31 - L31 -> 0 | AN31: =A31-AG31 -> 5 | AO31: =4 * PI() * 8.854187817E-12 * (I31 * 0.0000000001)^3 -> 8.4417396e-42 | AP31: =AO31 * 10^12 -> 8.4417396e-30 | AQ31: =(1 / (2 * 3.14159265358979)) * SQRT((A31 * (1.602176634E-19^2)) / ((AI31 * 1E-30) * 9.1093837015E-31 * 8.8541878128E-12)) -> 8.8677109e+16 | AR31: =I31 * 350 -> 148.16962 | AS31: =299792458000000000 / AQ31 -> 3.3807198
A32: 32 | B32: Germanium | C32: ge | D32: Metalloid | E32: 70 | F32: =E32-A32 -> 38 | G32: =(A32 * 1.007276) + (F32 * 1.008665) + (L32 * 0.00054858) -> 70.579657 | H32: =(G32-(A32*'Atomic Particles'!C1))/'Atomic Particles'!C2+A32 -> 70.017331 | I32: =0.529177210544 * (M32^2 / (A32 - AG32)) -> 0.37463873 | J32: =(('Atomic Particles'!C1)*A32)+(('Atomic Particles'!C2)*Elements!F32) -> 70.562176 | K32: =(E32^(1/3))*Constants!B2 -> 5.1516066e-15 | L32: 32 | M32: 2 | N32: 2 | O32: 6 | P32: 2 | Q32: 6 | R32: 10 | S32: 2 | T32: 2 | AF32: 4 | AG32: =IF(A32=1, 0, IF(A32=2, 0.3, IF(A32<=10, 0.35*(N32+O32-1)+0.85*M32, IF(A32<=18, 0.35*(P32+Q32-1)+0.85*(N32+O32)+M32, IF(A32<=36, 0.35*(S32+T32-1)+0.85*(P32+Q32+R32)+(M32+N32+O32), IF(A32<=54, 0.35*(W32+X32-1)+0.85*(S32+T32+U32)+(M32+N32+O32+P32+Q32+R32), IF(A32<=86, 0.35*(AA32+AB32-1)+0.85*(W32+X32+Y32+Z32)+(M32+N32+O32+P32+Q32+R32+S32+T32+U32+V32), IF(A32<=118, 0.35*(AD32+AE32-1)+0.85*(AA32+AB32+AC32)+(M32+N32+O32+P32+Q32+R32+S32+T32+U32+V32+W32+X32+Y32+Z32), 0)))))))) -> 26.35 | AH32: =(G32 * 1.6605E-24) / (AI32 * 1E-24) -> 532.09819 | AI32: =(4/3) * PI() * (I32^3) -> 0.22025544 | AJ32: =(A32*1.67262192369E-27 + F32*1.67492749804E-27 + L32*9.1093837015E-31) / 1.6605390666E-27 -> 70.579668 | AM32: =A32 - L32 -> 0 | AN32: =A32-AG32 -> 5.65 | AO32: =4 * PI() * 8.854187817E-12 * (I32 * 0.0000000001)^3 -> 5.850549e-42 | AP32: =AO32 * 10^12 -> 5.850549e-30 | AQ32: =(1 / (2 * 3.14159265358979)) * SQRT((A32 * (1.602176634E-19^2)) / ((AI32 * 1E-30) * 9.1093837015E-31 * 8.8541878128E-12)) -> 1.0822394e+17 | AR32: =I32 * 350 -> 131.12356 | AS32: =299792458000000000 / AQ32 -> 2.7701123
A33: 33 | B33: Arsenic | C33: As | D33: Metalloid | E33: 75 | F33: =E33-A33 -> 42 | G33: =(A33 * 1.007276) + (F33 * 1.008665) + (L33 * 0.00054858) -> 75.622141 | H33: =(G33-(A33*'Atomic Particles'!C1))/'Atomic Particles'!C2+A33 -> 75.01787 | I33: =0.529177210544 * (M33^2 / (A33 - AG33)) -> 0.33598553 | J33: =(('Atomic Particles'!C1)*A33)+(('Atomic Particles'!C2)*Elements!F33) -> 75.604117 | K33: =(E33^(1/3))*Constants!B2 -> 5.2714542e-15 | L33: 33 | M33: 2 | N33: 2 | O33: 6 | P33: 2 | Q33: 6 | R33: 10 | S33: 2 | T33: 3 | AF33: 4 | AG33: =IF(A33=1, 0, IF(A33=2, 0.3, IF(A33<=10, 0.35*(N33+O33-1)+0.85*M33, IF(A33<=18, 0.35*(P33+Q33-1)+0.85*(N33+O33)+M33, IF(A33<=36, 0.35*(S33+T33-1)+0.85*(P33+Q33+R33)+(M33+N33+O33), IF(A33<=54, 0.35*(W33+X33-1)+0.85*(S33+T33+U33)+(M33+N33+O33+P33+Q33+R33), IF(A33<=86, 0.35*(AA33+AB33-1)+0.85*(W33+X33+Y33+Z33)+(M33+N33+O33+P33+Q33+R33+S33+T33+U33+V33), IF(A33<=118, 0.35*(AD33+AE33-1)+0.85*(AA33+AB33+AC33)+(M33+N33+O33+P33+Q33+R33+S33+T33+U33+V33+W33+X33+Y33+Z33), 0)))))))) -> 26.7 | AH33: =(G33 * 1.6605E-24) / (AI33 * 1E-24) -> 790.38287 | AI33: =(4/3) * PI() * (I33^3) -> 0.15887309 | AJ33: =(A33*1.67262192369E-27 + F33*1.67492749804E-27 + L33*9.1093837015E-31) / 1.6605390666E-27 -> 75.622153 | AM33: =A33 - L33 -> 0 | AN33: =A33-AG33 -> 6.3 | AO33: =4 * PI() * 8.854187817E-12 * (I33 * 0.0000000001)^3 -> 4.2200764e-42 | AP33: =AO33 * 10^12 -> 4.2200764e-30 | AQ33: =(1 / (2 * 3.14159265358979)) * SQRT((A33 * (1.602176634E-19^2)) / ((AI33 * 1E-30) * 9.1093837015E-31 * 8.8541878128E-12)) -> 1.2940274e+17 | AR33: =I33 * 350 -> 117.59494 | AS33: =299792458000000000 / AQ33 -> 2.3167397
A34: 34 | B34: Selenium | C34: Se | D34: Nonmetal | E34: 77 | F34: =E34-A34 -> 43 | G34: =(A34 * 1.007276) + (F34 * 1.008665) + (L34 * 0.00054858) -> 77.638631 | H34: =(G34-(A34*'Atomic Particles'!C1))/'Atomic Particles'!C2+A34 -> 77.018411 | I34: =0.529177210544 * (M34^2 / (A34 - AG34)) -> 0.30456242 | J34: =(('Atomic Particles'!C1)*A34)+(('Atomic Particles'!C2)*Elements!F34) -> 77.62006 | K34: =(E34^(1/3))*Constants!B2 -> 5.3179011e-15 | L34: 34 | M34: 2 | N34: 2 | O34: 6 | P34: 2 | Q34: 6 | R34: 10 | S34: 2 | T34: 4 | AF34: 4 | AG34: =IF(A34=1, 0, IF(A34=2, 0.3, IF(A34<=10, 0.35*(N34+O34-1)+0.85*M34, IF(A34<=18, 0.35*(P34+Q34-1)+0.85*(N34+O34)+M34, IF(A34<=36, 0.35*(S34+T34-1)+0.85*(P34+Q34+R34)+(M34+N34+O34), IF(A34<=54, 0.35*(W34+X34-1)+0.85*(S34+T34+U34)+(M34+N34+O34+P34+Q34+R34), IF(A34<=86, 0.35*(AA34+AB34-1)+0.85*(W34+X34+Y34+Z34)+(M34+N34+O34+P34+Q34+R34+S34+T34+U34+V34), IF(A34<=118, 0.35*(AD34+AE34-1)+0.85*(AA34+AB34+AC34)+(M34+N34+O34+P34+Q34+R34+S34+T34+U34+V34+W34+X34+Y34+Z34), 0)))))))) -> 27.05 | AH34: =(G34 * 1.6605E-24) / (AI34 * 1E-24) -> 1089.4296 | AI34: =(4/3) * PI() * (I34^3) -> 0.11833619 | AJ34: =(A34*1.67262192369E-27 + F34*1.67492749804E-27 + L34*9.1093837015E-31) / 1.6605390666E-27 -> 77.638643 | AM34: =A34 - L34 -> 0 | AN34: =A34-AG34 -> 6.95 | AO34: =4 * PI() * 8.854187817E-12 * (I34 * 0.0000000001)^3 -> 3.1433124e-42 | AP34: =AO34 * 10^12 -> 3.1433124e-30 | AQ34: =(1 / (2 * 3.14159265358979)) * SQRT((A34 * (1.602176634E-19^2)) / ((AI34 * 1E-30) * 9.1093837015E-31 * 8.8541878128E-12)) -> 1.5219218e+17 | AR34: =I34 * 350 -> 106.59685 | AS34: =299792458000000000 / AQ34 -> 1.9698283
A35: 35 | B35: Bromine | C35: Br | D35: Halogen | E35: 81 | F35: =E35-A35 -> 46 | G35: =(A35 * 1.007276) + (F35 * 1.008665) + (L35 * 0.00054858) -> 81.67245 | H35: =(G35-(A35*'Atomic Particles'!C1))/'Atomic Particles'!C2+A35 -> 81.018951 | I35: =0.529177210544 * (M35^2 / (A35 - AG35)) -> 0.27851432 | J35: =(('Atomic Particles'!C1)*A35)+(('Atomic Particles'!C2)*Elements!F35) -> 81.653335 | K35: =(E35^(1/3))*Constants!B2 -> 5.4084359e-15 | L35: 35 | M35: 2 | N35: 2 | O35: 6 | P35: 2 | Q35: 6 | R35: 10 | S35: 2 | T35: 5 | AF35: 4 | AG35: =IF(A35=1, 0, IF(A35=2, 0.3, IF(A35<=10, 0.35*(N35+O35-1)+0.85*M35, IF(A35<=18, 0.35*(P35+Q35-1)+0.85*(N35+O35)+M35, IF(A35<=36, 0.35*(S35+T35-1)+0.85*(P35+Q35+R35)+(M35+N35+O35), IF(A35<=54, 0.35*(W35+X35-1)+0.85*(S35+T35+U35)+(M35+N35+O35+P35+Q35+R35), IF(A35<=86, 0.35*(AA35+AB35-1)+0.85*(W35+X35+Y35+Z35)+(M35+N35+O35+P35+Q35+R35+S35+T35+U35+V35), IF(A35<=118, 0.35*(AD35+AE35-1)+0.85*(AA35+AB35+AC35)+(M35+N35+O35+P35+Q35+R35+S35+T35+U35+V35+W35+X35+Y35+Z35), 0)))))))) -> 27.4 | AH35: =(G35 * 1.6605E-24) / (AI35 * 1E-24) -> 1498.5915 | AI35: =(4/3) * PI() * (I35^3) -> 0.090496379 | AJ35: =(A35*1.67262192369E-27 + F35*1.67492749804E-27 + L35*9.1093837015E-31) / 1.6605390666E-27 -> 81.672463 | AM35: =A35 - L35 -> 0 | AN35: =A35-AG35 -> 7.6 | AO35: =4 * PI() * 8.854187817E-12 * (I35 * 0.0000000001)^3 -> 2.4038158e-42 | AP35: =AO35 * 10^12 -> 2.4038158e-30 | AQ35: =(1 / (2 * 3.14159265358979)) * SQRT((A35 * (1.602176634E-19^2)) / ((AI35 * 1E-30) * 9.1093837015E-31 * 8.8541878128E-12)) -> 1.7657535e+17 | AR35: =I35 * 350 -> 97.480012 | AS35: =299792458000000000 / AQ35 -> 1.697816
A36: 36 | B36: Krypton | C36: Kr | D36: Noble Gas | E36: 83 | F36: =E36-A36 -> 47 | G36: =(A36 * 1.007276) + (F36 * 1.008665) + (L36 * 0.00054858) -> 83.68894 | H36: =(G36-(A36*'Atomic Particles'!C1))/'Atomic Particles'!C2+A36 -> 83.019493 | I36: =0.529177210544 * (M36^2 / (A36 - AG36)) -> 0.25657077 | J36: =(('Atomic Particles'!C1)*A36)+(('Atomic Particles'!C2)*Elements!F36) -> 83.669278 | K36: =(E36^(1/3))*Constants!B2 -> 5.4525883e-15 | L36: 36 | M36: 2 | N36: 2 | O36: 6 | P36: 2 | Q36: 6 | R36: 10 | S36: 2 | T36: 6 | AF36: 4 | AG36: =IF(A36=1, 0, IF(A36=2, 0.3, IF(A36<=10, 0.35*(N36+O36-1)+0.85*M36, IF(A36<=18, 0.35*(P36+Q36-1)+0.85*(N36+O36)+M36, IF(A36<=36, 0.35*(S36+T36-1)+0.85*(P36+Q36+R36)+(M36+N36+O36), IF(A36<=54, 0.35*(W36+X36-1)+0.85*(S36+T36+U36)+(M36+N36+O36+P36+Q36+R36), IF(A36<=86, 0.35*(AA36+AB36-1)+0.85*(W36+X36+Y36+Z36)+(M36+N36+O36+P36+Q36+R36+S36+T36+U36+V36), IF(A36<=118, 0.35*(AD36+AE36-1)+0.85*(AA36+AB36+AC36)+(M36+N36+O36+P36+Q36+R36+S36+T36+U36+V36+W36+X36+Y36+Z36), 0)))))))) -> 27.75 | AH36: =(G36 * 1.6605E-24) / (AI36 * 1E-24) -> 1964.2502 | AI36: =(4/3) * PI() * (I36^3) -> 0.070747343 | AJ36: =(A36*1.67262192369E-27 + F36*1.67492749804E-27 + L36*9.1093837015E-31) / 1.6605390666E-27 -> 83.688953 | AM36: =A36 - L36 -> 0 | AN36: =A36-AG36 -> 8.25 | AO36: =4 * PI() * 8.854187817E-12 * (I36 * 0.0000000001)^3 -> 1.8792308e-42 | AP36: =AO36 * 10^12 -> 1.8792308e-30 | AQ36: =(1 / (2 * 3.14159265358979)) * SQRT((A36 * (1.602176634E-19^2)) / ((AI36 * 1E-30) * 9.1093837015E-31 * 8.8541878128E-12)) -> 2.0253862e+17 | AR36: =I36 * 350 -> 89.799769 | AS36: =299792458000000000 / AQ36 -> 1.4801743
A37: 37 | B37: Rubidium | C37: Rb | D37: Alkali Metal | E37: 85 | F37: =E37-A37 -> 48 | G37: =(A37 * 1.007276) + (F37 * 1.008665) + (L37 * 0.00054858) -> 85.705429 | H37: =(G37-(A37*'Atomic Particles'!C1))/'Atomic Particles'!C2+A37 -> 85.020035 | I37: =0.529177210544 * (M37^2 / (A37 - AG37)) -> 0.96214038 | J37: =(('Atomic Particles'!C1)*A37)+(('Atomic Particles'!C2)*Elements!F37) -> 85.685221 | K37: =(E37^(1/3))*Constants!B2 -> 5.4960371e-15 | L37: 37 | M37: 2 | N37: 2 | O37: 6 | P37: 2 | Q37: 6 | R37: 10 | S37: 2 | T37: 6 | W37: 1 | AF37: 5 | AG37: =IF(A37=1, 0, IF(A37=2, 0.3, IF(A37<=10, 0.35*(N37+O37-1)+0.85*M37, IF(A37<=18, 0.35*(P37+Q37-1)+0.85*(N37+O37)+M37, IF(A37<=36, 0.35*(S37+T37-1)+0.85*(P37+Q37+R37)+(M37+N37+O37), IF(A37<=54, 0.35*(W37+X37-1)+0.85*(S37+T37+U37)+(M37+N37+O37+P37+Q37+R37), IF(A37<=86, 0.35*(AA37+AB37-1)+0.85*(W37+X37+Y37+Z37)+(M37+N37+O37+P37+Q37+R37+S37+T37+U37+V37), IF(A37<=118, 0.35*(AD37+AE37-1)+0.85*(AA37+AB37+AC37)+(M37+N37+O37+P37+Q37+R37+S37+T37+U37+V37+W37+X37+Y37+Z37), 0)))))))) -> 34.8 | AH37: =(G37 * 1.6605E-24) / (AI37 * 1E-24) -> 38.145497 | AI37: =(4/3) * PI() * (I37^3) -> 3.7308169 | AJ37: =(A37*1.67262192369E-27 + F37*1.67492749804E-27 + L37*9.1093837015E-31) / 1.6605390666E-27 -> 85.705443 | AM37: =A37 - L37 -> 0 | AN37: =A37-AG37 -> 2.2 | AO37: =4 * PI() * 8.854187817E-12 * (I37 * 0.0000000001)^3 -> 9.9100061e-41 | AP37: =AO37 * 10^12 -> 9.9100061e-29 | AQ37: =(1 / (2 * 3.14159265358979)) * SQRT((A37 * (1.602176634E-19^2)) / ((AI37 * 1E-30) * 9.1093837015E-31 * 8.8541878128E-12)) -> 2.8275517e+16 | AR37: =I37 * 350 -> 336.74913 | AS37: =299792458000000000 / AQ37 -> 10.602546
